Workbook
Name IQ_CH: 110000
Name IQ_CQ: 5000
Name IQ_CY: 10000
Name IQ_DAILY: 500000
Name IQ_FH: 100000
Name IQ_FQ: 500
Name IQ_FY: 1000
Name IQ_LTM: 2000
Name IQ_MONTH: 15000
Name IQ_NTM: 6000
Name IQ_WEEK: 50000
Name IQ_YTD: 3000

Sheet List Manager - Companies
A2: List Manager - Companies
A3: List Name | B3: Stock Pick
A4: Entity Type | B4: Company -> Companies | C4: Owner | D4: Lorena Assumpcao
A5: List Description
A8: Company | B8: Ticker | C8: Source | D8: Market Cap ($M) | E8: Price ($) | F8: YTD Price Change (%) | G8: PE (x)
A9: Alphabet Inc. (NASDAQGS:GOOGL) | B9: GOOGL (NASDAQGS) | C9: Static | D9: 2184120.1 | E9: 179.53 | F9: -5.2 | G9: 20.01
A10: Amazon.com, Inc. (NASDAQGS:AMZN) | B10: AMZN (NASDAQGS) | C10: Static | D10: 2371799.3 | E10: 223.41 | F10: 1.8 | G10: 36.39
A11: Ball Corporation (NYSE:BALL) | B11: BALL (NYSE) | C11: Static | D11: 16292.7 | E11: 58.73 | F11: 6.5 | G11: -
A12: Equinix, Inc. (NASDAQGS:EQIX) | B12: EQIX (NASDAQGS) | C12: Static | D12: 76983.5 | E12: 787 | F12: -16.5 | G12: 81.81
A13: Honeywell International Inc. (NASDAQGS:HON) | B13: HON (NASDAQGS) | C13: Static | D13: 154501 | E13: 240.4 | F13: 6.4 | G13: -
A14: Mastercard Incorporated (NYSE:MA) | B14: MA (NYSE) | C14: Static | D14: 516897 | E14: 569.24 | F14: 8.1 | G14: 39.92
A15: NextEra Energy, Inc. (NYSE:NEE) | B15: NEE (NYSE) | C15: Static | D15: 152091.7 | E15: 73.88 | F15: 3.1 | G15: 27.67
A16: NVIDIA Corporation (NASDAQGS:NVDA) | B16: NVDA (NASDAQGS) | C16: Static | D16: 3887896 | E16: 159.34 | F16: 18.7 | G16: -
A17: Schlumberger Limited (NYSE:SLB) | B17: SLB (NYSE) | C17: Static | D17: 48489.8 | E17: 35.65 | F17: -7 | G17: -
A18: The Procter & Gamble Company (NYSE:PG) | B18: PG (NYSE) | C18: Static | D18: 377072.7 | E18: 160.83 | F18: -4.1 | G18: -
A19: UnitedHealth Group Incorporated (NYSE:UNH) | B19: UNH (NYSE) | C19: Static | D19: 279898.2 | E19: 308.55 | F19: -39 | G19: 12.92

Sheet Expected Return
B3: Assumptions
B4: Risk-fee rate | C4: 0.0209 | E4: in Jan 2016 | F4: https://www.macrotrends.net/2016/10-year-treasury-bond-rate-yield-chart
B5: Market Return | C5: 0.0954 | E5: in Jan 2016 | F5: https://www.macrotrends.net/2526/sp-500-historical-annual-returns
B6: Beta | C6: Long Term Beta | E6: in Jan 2016 | F6: long-term from Capital IQ pro
B7: Company | C7: Ticker | D7: Source | E7: Market Cap ($M) | F7: Price ($) | G7: Beta | H7: Expected return
B8: Alphabet Inc. (NASDAQGS:GOOGL) | C8: GOOGL | D8: Static | E8: 2144839.7 | F8: 176.23 | G8: 1.09 | H8: ='Expected Return'!$C$4+'Expected Return'!G8*('Expected Return'!$C$5-'Expected Return'!$C$4) -> 0.102105
B9: Amazon.com, Inc. (NASDAQGS:AMZN) | C9: AMZN | D9: Static | E9: 2329121.6 | F9: 219.39 | G9: 1.24 | H9: ='Expected Return'!$C$4+'Expected Return'!G9*('Expected Return'!$C$5-'Expected Return'!$C$4) -> 0.11328
B10: BALL CORPORATION | C10: BALL | D10: Static | G10: 0.9 | H10: ='Expected Return'!$C$4+'Expected Return'!G10*('Expected Return'!$C$5-'Expected Return'!$C$4) -> 0.08795
B11: Equinix, Inc. (NASDAQGS:EQIX) | C11: EQIX | D11: Static | E11: 77812.1 | F11: 795.47 | G11: 0.97 | H11: ='Expected Return'!$C$4+'Expected Return'!G11*('Expected Return'!$C$5-'Expected Return'!$C$4) -> 0.093165
B12: Honeywell International Inc. (NASDAQGS:HON) | C12: HON | D12: Static | E12: 149668 | F12: 232.88 | G12: 1.13 | H12: ='Expected Return'!$C$4+'Expected Return'!G12*('Expected Return'!$C$5-'Expected Return'!$C$4) -> 0.105085
B13: Mastercard Incorporated (NYSE:MA) | C13: MA | D13: Static | E13: 510268.3 | F13: 561.94 | G13: 1.22 | H13: ='Expected Return'!$C$4+'Expected Return'!G13*('Expected Return'!$C$5-'Expected Return'!$C$4) -> 0.11179
B14: NextEra Energy, Inc. (NYSE:NEE) | C14: NEE | D14: Static | E14: 142910.2 | F14: 69.42 | G14: 0.66 | H14: ='Expected Return'!$C$4+'Expected Return'!G14*('Expected Return'!$C$5-'Expected Return'!$C$4) -> 0.07007
B15: Schlumberger Limited | C15: SLB | D15: Static | G15: 1.09 | H15: ='Expected Return'!$C$4+'Expected Return'!G15*('Expected Return'!$C$5-'Expected Return'!$C$4) -> 0.102105
B16: NVIDIA Corporation (NASDAQGS:NVDA) | C16: NVDA | D16: Static | E16: 3854956 | F16: 157.99 | G16: 1.14 | H16: ='Expected Return'!$C$4+'Expected Return'!G16*('Expected Return'!$C$5-'Expected Return'!$C$4) -> 0.10583
B17: The Procter & Gamble Company (NYSE:PG) | C17: PG | D17: Static | E17: 373532.4 | F17: 159.32 | G17: 0.67 | H17: ='Expected Return'!$C$4+'Expected Return'!G17*('Expected Return'!$C$5-'Expected Return'!$C$4) -> 0.070815
B18: UnitedHealth Group Incorporated (NYSE:UNH) | C18: UNH | D18: Static | E18: 283000.6 | F18: 311.97 | G18: 0.96 | H18: ='Expected Return'!$C$4+'Expected Return'!G18*('Expected Return'!$C$5-'Expected Return'!$C$4) -> 0.09242

Sheet Optimatization
F1: Porfolio Stats
B2: Risk-fee rate | C2: 0.0209 | D2: in Jan 2016 | F2: Sharpe Ratio | G2: =(G3-C2)/G4 -> 0.83896628
B3: Market Return | C3: 0.0954 | D3: in Jan 2016 | F3: Expected Return | G3: =E8*I8+E18*I18+E17*I17+E16*I16+E15*I15+E14*I14+E13*I13+E12*I12+E11*I11+E10*I10+E9*I9 -> 0.10254455
F4: SD | G4: {=SQRT(MMULT(MMULT(TRANSPOSE(G8:H18),L8:V18),G8:H18*252))} -> 0.097315651
F5: Total Weight | G5: =SUM(I8:I18) -> 1
K6: Covariance Matrix
B7: Company | C7: Ticker | D7: Beta | E7: Expected return | F7: ST. D | G7: MinWe | H7: MaxWe | I7: Weights | L7: GOOGL | M7: AMZN | N7: BALL | O7: EQIX | P7: HON | Q7: MA | R7: NEE | S7: NRG | T7: NVDA | U7: PG | V7: UNH
B8: Alphabet Inc. (NASDAQGS:GOOGL) | C8: GOOGL | D8: 1.09 | E8: 0.102105 | F8: 0.20601666 | G8: 0.08 | H8: 0.17 | I8: 0.17 | K8: GOOGL | L8: =VARP(Rawdata2!$O$13:$O$263) -> 0.00033037657 | M8: 0.00022498847 | N8: 7.5807133e-05 | O8: 9.6828554e-05 | P8: 0.00011340713 | Q8: 0.00012306595 | R8: 5.501935e-05 | S8: 5.8457372e-05 | T8: 0.00011011161 | U8: 7.839971e-05 | V8: 0.00010663388
B9: Amazon.com, Inc. (NASDAQGS:AMZN) | C9: AMZN | D9: 1.24 | E9: 0.11328 | F9: 0.29779313 | G9: 0.08 | H9: 0.17 | I9: 0.17 | K9: AMZN | L9: 0.00022498847 | M9: =VARP(Rawdata2!$P$13:$P$263) -> 0.00044687457 | N9: 0.00010245587 | O9: 0.00012059385 | P9: 9.8848597e-05 | Q9: 0.00014951882 | R9: 5.7775439e-05 | S9: 8.124702e-05 | T9: 9.2840479e-05 | U9: 7.4856902e-05 | V9: 0.0001171056
B10: BALL CORPORATION | C10: BALL | D10: 0.9 | E10: 0.08795 | F10: 0.17361542 | G10: 0.03 | H10: 0.05 | I10: 0.03 | K10: BALL | L10: 7.5807133e-05 | M10: 0.00010245587 | N10: =VARP(Rawdata2!$Q$13:$Q$263) -> 0.00023998013 | O10: 9.6426943e-05 | P10: 0.00010886015 | Q10: 9.7256183e-05 | R10: 6.5543792e-05 | S10: 0.00012633771 | T10: 0.00011406683 | U10: 7.2523798e-05 | V10: 9.9111147e-05
B11: Equinix, Inc. (NASDAQGS:EQIX) | C11: EQIX | D11: 0.97 | E11: 0.093165 | F11: 0.18203928 | G11: 0.06 | H11: 0.12 | I11: 0.12 | K11: EQIX | L11: 9.6828554e-05 | M11: 0.00012059385 | N11: 9.6426943e-05 | O11: =VARP(Rawdata2!$R$13:$R$263) -> 0.00021248236 | P11: 9.583811e-05 | Q11: 0.00011083505 | R11: 7.4523423e-05 | S11: 6.3189814e-05 | T11: 0.00010881748 | U11: 6.6071332e-05 | V11: 0.00011225788
B12: Honeywell International Inc. (NASDAQGS:HON) | C12: HON | D12: 1.13 | E12: 0.105085 | F12: 0.1209896 | G12: 0.05 | H12: 0.1 | I12: 0.1 | K12: HON | L12: 0.00011340713 | M12: 9.8848597e-05 | N12: 0.00010886015 | O12: 9.583811e-05 | P12: =VARP(Rawdata2!$S$13:$S$263) -> 0.00015803506 | Q12: 0.00011574313 | R12: 7.5322653e-05 | S12: 9.1091797e-05 | T12: 0.00012407767 | U12: 7.3193908e-05 | V12: 9.0080359e-05
B13: Mastercard Incorporated (NYSE:MA) | C13: MA | D13: 1.22 | E13: 0.11179 | F13: 0.18261439 | G13: 0.05 | H13: 0.1 | I13: 0.1 | K13: MA | L13: 0.00012306595 | M13: 0.00014951882 | N13: 9.7256183e-05 | O13: 0.00011083505 | P13: 0.00011574313 | Q13: =VARP(Rawdata2!$T$13:$T$263) -> 0.00017197151 | R13: 6.3499421e-05 | S13: 5.8885848e-05 | T13: 0.00013302886 | U13: 8.1002493e-05 | V13: 0.0001025999
B14: NextEra Energy, Inc. (NYSE:NEE) | C14: NEE | D14: 0.66 | E14: 0.07007 | F14: 0.16759034 | G14: 0.03 | H14: 0.06 | I14: 0.03 | K14: NEE | L14: 5.501935e-05 | M14: 5.7775439e-05 | N14: 6.5543792e-05 | O14: 7.4523423e-05 | P14: 7.5322653e-05 | Q14: 6.3499421e-05 | R14: =VARP(Rawdata2!$U$13:$U$263) -> 0.00014295804 | S14: 0.00010939862 | T14: 6.1846327e-05 | U14: 5.9145579e-05 | V14: 6.1102839e-05
B15: Schlumberger Limited | C15: SLB | D15: 1.09 | E15: 0.102105 | F15: 0.17 | G15: 0.02 | H15: 0.04 | I15: 0.02 | K15: NRG | L15: 5.8457372e-05 | M15: 8.124702e-05 | N15: 0.00012633771 | O15: 6.3189814e-05 | P15: 9.1091797e-05 | Q15: 5.8885848e-05 | R15: 0.00010939862 | S15: =VARP(Rawdata2!$V$13:$V$263) -> 0.00026454962 | T15: 5.0229012e-05 | U15: 2.2972918e-05 | V15: 3.1253359e-05
B16: NVIDIA Corporation (NASDAQGS:NVDA) | C16: NVDA | D16: 1.14 | E16: 0.10583 | F16: 0.23313539 | G16: 0.08 | H16: 0.2 | I16: 0.2 | K16: NVDA | L16: 0.00011011161 | M16: 9.2840479e-05 | N16: 0.00011406683 | O16: 0.00010881748 | P16: 0.00012407767 | Q16: 0.00013302886 | R16: 6.1846327e-05 | S16: 5.0229012e-05 | T16: =VARP(Rawdata2!$W$13:$W$263) -> 0.00047206075 | U16: 8.3168232e-05 | V16: 0.00010689607
B17: The Procter & Gamble Company (NYSE:PG) | C17: PG | D17: 0.67 | E17: 0.070815 | F17: 0.14092546 | G17: 0.02 | H17: 0.04 | I17: 0.02 | K17: PG | L17: 7.839971e-05 | M17: 7.4856902e-05 | N17: 7.2523798e-05 | O17: 6.6071332e-05 | P17: 7.3193908e-05 | Q17: 8.1002493e-05 | R17: 5.9145579e-05 | S17: 2.2972918e-05 | T17: 8.3168232e-05 | U17: =VARP(Rawdata2!$X$13:$X$263) -> 0.00010392295 | V17: 7.4734808e-05
B18: UnitedHealth Group Incorporated (NYSE:UNH) | C18: UNH | D18: 0.96 | E18: 0.09242 | F18: 0.16456335 | G18: 0.04 | H18: 0.07 | I18: 0.04 | K18: UNH | L18: 0.00010663388 | M18: 0.0001171056 | N18: 9.9111147e-05 | O18: 0.00011225788 | P18: 9.0080359e-05 | Q18: 0.0001025999 | R18: 6.1102839e-05 | S18: 3.1253359e-05 | T18: 0.00010689607 | U18: 7.4734808e-05 | V18: =VARP(Rawdata2!$Y$13:$Y$263) -> 0.00025478705

Sheet RawData
A1: Dates
A2: Start Date | B2: 41275
A3: End | B3: 42369
A4: Interval | B4: 2 | AE4: GOOGL | AF4: AMZN | AG4: BALL | AH4: EQIX | AI4: HON | AJ4: MA | AK4: NEE | AL4: NRG | AM4: NVDA | AN4: PG | AO4: UNH
AD5: GOOGL | AE5: =VARP(RawData!$P$13:$P$766) -> 0.00022428413
AD6: AMZN | AE6: 0.00014843626 | AF6: =VARP(RawData!$Q$13:$Q$766) -> 0.00038054585
AD7: BALL | AE7: 1.7238044e-05 | AF7: 3.6144937e-05 | AG7: =VARP(RawData!$R$13:$R$766) -> 0.00015223469
AD8: EQIX | AE8: 7.4285768e-05 | AF8: 9.2291981e-05 | AG8: 2.6090872e-05 | AH8: =VARP(RawData!$S$13:$S$766) -> 0.00021996378
B9: Company | C9: #VALUE! | D9: #VALUE! | E9: BALL CORPORATION (XNYS:BALL) | F9: #VALUE! | G9: #VALUE! | H9: #VALUE! | I9: #VALUE! | J9: #VALUE! | K9: #VALUE! | L9: #VALUE! | M9: #VALUE! | N9: SPY | P9: RETURNS | AD9: HON | AE9: 2.3077031e-05 | AF9: 3.3215985e-05 | AG9: 7.2266724e-05 | AH9: 2.0531455e-05 | AI9: =VARP(RawData!$T$13:$T$766) -> 0.00012198572
B10: Ticker | C10: GOOGL | D10: AMZN | E10: BALL | F10: EQIX | G10: HON | H10: MA | I10: NEE | J10: SLB | K10: NVDA | L10: PG | M10: UNH | O10: Ticker | P10: GOOGL | Q10: AMZN | R10: BALL | S10: EQIX | T10: HON | U10: MA | V10: NEE | W10: SLB | X10: NVDA | Y10: PG | Z10: UNH | AD10: MA | AE10: 2.7015478e-05 | AF10: 3.5706443e-05 | AG10: 6.1380852e-05 | AH10: 2.0287794e-05 | AI10: 8.7705436e-05 | AJ10: =VARP(RawData!$U$13:$U$766) -> 0.00017670554
B11: {=_xlfn.STOCKHISTORY(C10,B2,B3,0,1,0,1)} -> Date | C11: Close | D11: {=_xlfn.STOCKHISTORY(D10,$B$2,$B$3,0,1,1)} -> Close | E11: {=_xlfn.STOCKHISTORY(E10,$B$2,$B$3,0,1,1)} -> Close | F11: {=_xlfn.STOCKHISTORY(F10,$B$2,$B$3,0,1,1)} -> Close | G11: {=_xlfn.STOCKHISTORY(G10,$B$2,$B$3,0,1,1)} -> Close | H11: {=_xlfn.STOCKHISTORY(H10,$B$2,$B$3,0,1,1)} -> Close | I11: {=_xlfn.STOCKHISTORY(I10,$B$2,$B$3,0,1,1)} -> Close | J11: {=_xlfn.STOCKHISTORY(J10,$B$2,$B$3,0,1,1)} -> Close | K11: {=_xlfn.STOCKHISTORY(K10,$B$2,$B$3,0,1,1)} -> Close | ... M11: {=_xlfn.STOCKHISTORY(M10,$B$2,$B$3,0,1,1)} -> Close | N11: SPY | AD11: NEE | AE11: 7.4534545e-06 | AF11: 3.9982461e-06 | AG11: 4.3607741e-05 | AH11: 1.195097e-05 | AI11: 5.209718e-05 | AJ11: 4.9114471e-05 | AK11: =VARP(RawData!$V$13:$V$766) -> 0.00011067124
B12: 41276 | C12: 18.0988 | D12: 12.8655 | E12: 23.025 | F12: 207.2725 | G12: 61.6417 | H12: 51.027 | I12: 17.63 | J12: 71.4 | K12: 0.318 | L12: 69.39 | M12: 54.54 | N12: 146.06 | P12: GOOGL | Q12: AMZN | R12: BALL | S12: EQIX | T12: HON | U12: MA | V12: NEE | W12: SLB | X12: NVDA | Y12: PG | Z12: UNH | AA12: SPY | AD12: NRG | AE12: 1.7238227e-05 | AF12: 2.6751797e-05 | AG12: 6.9947091e-05 | AH12: 1.6802321e-05 | AI12: 6.0321598e-05 | AJ12: 4.6275385e-05 | AK12: 8.2252446e-05 | AL12: =VARP(RawData!$W$13:$W$766) -> 0.00021611632
B13: 41277 | C13: 18.1093 | D13: 12.924 | E13: 23.22 | F13: 204.4769 | G13: 61.8797 | H13: 51.1 | I13: 17.6325 | J13: 70.92 | K13: 0.3183 | L13: 68.95 | M13: 51.99 | N13: 145.7341 | P13: =LN(C13/C12) -> 0.00057998074 | Q13: =LN(D13/D12) -> 0.0045367378 | R13: =LN(E13/E12) -> 0.0084333941 | S13: =LN(F13/F12) -> -0.013579342 | T13: =LN(G13/G12) -> 0.003853588 | U13: =LN(H13/H12) -> 0.0014295928 | V13: =LN(I13/I12) -> 0.00014179369 | W13: =LN(J13/J12) -> -0.0067453881 | ... AA13: =LN(N13/N12) -> -0.0022337678 | AD13: NVDA | AE13: 8.5089582e-05 | AF13: 9.1508276e-05 | AG13: 3.0594719e-05 | AH13: 7.6259769e-05 | AI13: 2.8323963e-05 | AJ13: 2.6928169e-05 | AK13: 1.4331214e-05 | AL13: 4.1453043e-05 | AM13: =VARP(RawData!$X$13:$X$766) -> 0.00029539865
B14: 41278 | C14: 18.4671 | D14: 12.9575 | E14: 23.25 | F14: 207.5135 | G14: 63.1459 | H14: 51.098 | I14: 17.72 | J14: 72.01 | K14: 0.3288 | L14: 69.09 | M14: 52.09 | N14: 146.37 | P14: =LN(C14/C13) -> 0.019565152 | Q14: =LN(D14/D13) -> 0.0025887231 | R14: =LN(E14/E13) -> 0.0012911558 | S14: =LN(F14/F13) -> 0.014741387 | T14: =LN(G14/G13) -> 0.020255744 | U14: =LN(H14/H13) -> -3.9139709e-05 | V14: =LN(I14/I13) -> 0.0049501551 | W14: =LN(J14/J13) -> 0.015252517 | ... AA14: =LN(N14/N13) -> 0.0043539341 | AD14: PG | AE14: 7.2690228e-06 | AF14: 1.3932236e-06 | AG14: 4.0187215e-05 | AH14: 1.3192323e-05 | AI14: 4.629761e-05 | AJ14: 5.2562844e-05 | AK14: 3.8380142e-05 | AL14: 2.3199117e-05 | AM14: 1.3366626e-05 | AN14: =VARP(RawData!$Y$13:$Y$766) -> 8.843362e-05
B15: 41281 | C15: 18.3866 | D15: 13.423 | E15: 23.045 | F15: 210.9069 | G15: 63.1744 | H15: 51.953 | I15: 17.6373 | J15: 72.21 | K15: 0.3193 | L15: 68.62 | M15: 52.09 | N15: 145.9695 | P15: =LN(C15/C14) -> -0.0043686321 | Q15: =LN(D15/D14) -> 0.035294882 | R15: =LN(E15/E14) -> -0.0088563059 | S15: =LN(F15/F14) -> 0.016220406 | T15: =LN(G15/G14) -> 0.00045123389 | U15: =LN(H15/H14) -> 0.016594106 | V15: =LN(I15/I14) -> -0.0046779675 | W15: =LN(J15/J14) -> 0.0027735422 | ... AA15: =LN(N15/N14) -> -0.0027399667 | AD15: UNH | AE15: 7.9761036e-06 | AF15: 9.8104194e-06 | AG15: 6.0956829e-05 | AH15: 1.3113014e-05 | AI15: 6.6646217e-05 | AJ15: 7.2141514e-05 | AK15: 3.646059e-05 | AL15: 3.2470317e-05 | AM15: 1.7326505e-05 | AN15: 4.3671157e-05 | AO15: =VARP(RawData!$Z$13:$Z$766) -> 0.00018834482
B16: 41282 | C16: 18.3503 | D16: 13.319 | E16: 22.705 | F16: 207.4653 | G16: 62.5842 | H16: 51.782 | I16: 17.825 | J16: 72.51 | K16: 0.3123 | L16: 68.51 | M16: 51.4 | N16: 145.5496 | P16: =LN(C16/C15) -> -0.0019762153 | Q16: =LN(D16/D15) -> -0.0077780663 | R16: =LN(E16/E15) -> -0.014863662 | S16: =LN(F16/F15) -> -0.016452707 | T16: =LN(G16/G15) -> -0.0093863057 | U16: =LN(H16/H15) -> -0.0032968652 | V16: =LN(I16/I15) -> 0.010585989 | W16: =LN(J16/J15) -> 0.0041459429 | ... AA16: =LN(N16/N15) -> -0.0028807738
B17: 41283 | C17: 18.4708 | D17: 13.3175 | E17: 22.805 | F17: 210.0007 | G17: 63.3458 | H17: 53.239 | I17: 17.7 | J17: 72.2 | K17: 0.3053 | L17: 68.88 | M17: 52.37 | N17: 145.92 | P17: =LN(C17/C16) -> 0.0065451836 | Q17: =LN(D17/D16) -> -0.00011262741 | R17: =LN(E17/E16) -> 0.0043946456 | S17: =LN(F17/F16) -> 0.012146767 | T17: =LN(G17/G16) -> 0.012095756 | U17: =LN(H17/H16) -> 0.027748612 | V17: =LN(I17/I16) -> -0.0070373267 | W17: =LN(J17/J16) -> -0.0042844375 | ... AA17: =LN(N17/N16) -> 0.0025416043
B18: 41284 | C18: 18.555 | D18: 13.267 | E18: 22.805 | F18: 209.9428 | G18: 63.2316 | H18: 52.765 | I18: 17.8725 | J18: 73.25 | K18: 0.3058 | L18: 69.27 | M18: 53.11 | N18: 147.08 | P18: =LN(C18/C17) -> 0.0045481878 | Q18: =LN(D18/D17) -> -0.0037992109 | R18: =LN(E18/E17) -> 0 | S18: =LN(F18/F17) -> -0.00027575138 | T18: =LN(G18/G17) -> -0.00180443 | U18: =LN(H18/H17) -> -0.0089431184 | V18: =LN(I18/I17) -> 0.0096985791 | W18: =LN(J18/J17) -> 0.014438202 | ... AA18: =LN(N18/N17) -> 0.0079181301 | AD18: BETA 3 years study
B19: 41285 | C19: 18.5177 | D19: 13.397 | E19: 22.7 | F19: 209.885 | G19: 63.1268 | H19: 52.868 | I19: 17.945 | J19: 73.75 | K19: 0.3053 | L19: 69.22 | M19: 52.82 | N19: 147.07 | P19: =LN(C19/C18) -> -0.0020122631 | Q19: =LN(D19/D18) -> 0.0097510524 | R19: =LN(E19/E18) -> -0.0046148857 | S19: =LN(F19/F18) -> -0.00027535099 | T19: =LN(G19/G18) -> -0.0016587742 | U19: =LN(H19/H18) -> 0.0019501488 | V19: =LN(I19/I18) -> 0.0040483059 | W19: =LN(J19/J18) -> 0.0068027473 | ... AA19: =LN(N19/N18) -> -6.7992521e-05 | AD19: Assumptions | AF19: SPY | AG19: =EXP(AVERAGE(AA13:AA766)*252)-1 -> 0.1216603
B20: 41288 | C20: 18.0988 | D20: 13.6365 | E20: 22.795 | F20: 208.2655 | G20: 63.5552 | H20: 52.351 | I20: 17.9225 | J20: 72.77 | K20: 0.305 | L20: 69.63 | M20: 53.36 | N20: 146.97 | P20: =LN(C20/C19) -> -0.022881394 | Q20: =LN(D20/D19) -> 0.01771922 | R20: =LN(E20/E19) -> 0.0041762892 | S20: =LN(F20/F19) -> -0.0077460536 | T20: =LN(G20/G19) -> 0.0067634176 | U20: =LN(H20/H19) -> -0.0098272016 | V20: =LN(I20/I19) -> -0.0012546179 | W20: =LN(J20/J19) -> -0.013377213 | ... AA20: =LN(N20/N19) -> -0.00068017959 | AD20: Risk-fee rate | AE20: 0.0209
B21: 41289 | C21: 18.1408 | D21: 13.595 | E21: 22.885 | F21: 208.9885 | G21: 63.6695 | H21: 52.28 | I21: 17.97 | J21: 72.59 | K21: 0.2995 | L21: 69.88 | M21: 53.62 | N21: 147.07 | P21: =LN(C21/C20) -> 0.0023179074 | Q21: =LN(D21/D20) -> -0.0030479432 | R21: =LN(E21/E20) -> 0.0039404604 | S21: =LN(F21/F20) -> 0.0034655185 | T21: =LN(G21/G20) -> 0.0017968214 | U21: =LN(H21/H20) -> -0.0013571506 | V21: =LN(I21/I20) -> 0.0026467941 | W21: =LN(J21/J20) -> -0.0024766111 | ... AA21: =LN(N21/N20) -> 0.00068017959 | AD21: Market Return | AE21: 0.0954
B22: 41290 | C22: 17.8971 | D22: 13.4465 | E22: 22.755 | F22: 208.68 | G22: 63.5267 | H22: 52.129 | I22: 17.8275 | J22: 73.22 | K22: 0.3023 | L22: 69.34 | M22: 53.66 | N22: 147.05 | P22: =LN(C22/C21) -> -0.013524857 | Q22: =LN(D22/D21) -> -0.010983229 | R22: =LN(E22/E21) -> -0.0056967726 | S22: =LN(F22/F21) -> -0.0014772484 | T22: =LN(G22/G21) -> -0.002245351 | U22: =LN(H22/H21) -> -0.002892473 | V22: =LN(I22/I21) -> -0.0079614919 | W22: =LN(J22/J21) -> 0.0086414364 | ... AA22: =LN(N22/N21) -> -0.00013599891 | AD22: Beta | AE22: monthly
B23: 41291 | C23: 17.8002 | D23: 13.524 | E23: 23.155 | F23: 210.6369 | G23: 64.0788 | H23: 52.335 | I23: 17.77 | J23: 73.37 | K23: 0.3063 | L23: 69.67 | M23: 54.4 | N23: 148 | P23: =LN(C23/C22) -> -0.0054289954 | Q23: =LN(D23/D22) -> 0.0057470357 | R23: =LN(E23/E22) -> 0.017425838 | S23: =LN(F23/F22) -> 0.0093338199 | T23: =LN(G23/G22) -> 0.008653286 | U23: =LN(H23/H22) -> 0.0039439475 | V23: =LN(I23/I22) -> -0.0032305668 | W23: =LN(J23/J22) -> 0.002046525 | ... AA23: =LN(N23/N22) -> 0.0064396088 | AD23: Company | AE23: Ticker | AF23: Stock R | AG23: Beta 3Years | AH23: CAPM
B24: 41292 | C24: 17.6298 | D24: 13.606 | E24: 23.325 | F24: 212.0444 | G24: 64.5548 | H24: 52.1 | I24: 17.8875 | J24: 76.5 | K24: 0.3043 | L24: 69.94 | M24: 54.56 | N24: 148.33 | P24: =LN(C24/C23) -> -0.0096190411 | Q24: =LN(D24/D23) -> 0.0060449871 | R24: =LN(E24/E23) -> 0.0073150068 | S24: =LN(F24/F23) -> 0.0066598887 | T24: =LN(G24/G23) -> 0.0074008995 | U24: =LN(H24/H23) -> -0.0045004145 | V24: =LN(I24/I23) -> 0.0065905027 | W24: =LN(J24/J23) -> 0.041775608 | ... AA24: =LN(N24/N23) -> 0.0022272476 | AD24: Alphabet Inc. (NASDAQGS:GOOGL) | AE24: GOOGL | AF24: =EXP(AVERAGE(RawData!P13:P766)*252)-1 -> 0.29818694 | AG24: =SLOPE(P13:P766,$AA$13:$AA$766) -> 1.0812017 | AH24: =$AE$20+AG24*($AE$21-$AE$20) -> 0.10144953
B25: 41296 | C25: 17.5888 | D25: 13.5095 | E25: 23.27 | F25: 214.3098 | G25: 65.1165 | H25: 51.976 | I25: 17.995 | J25: 78 | K25: 0.3028 | L25: 69.95 | M25: 56.02 | N25: 149.13 | P25: =LN(C25/C24) -> -0.0023283162 | Q25: =LN(D25/D24) -> -0.0071177303 | R25: =LN(E25/E24) -> -0.0023607694 | S25: =LN(F25/F24) -> 0.010626945 | T25: =LN(G25/G24) -> 0.0086634978 | U25: =LN(H25/H24) -> -0.0023828752 | V25: =LN(I25/I24) -> 0.0059917966 | W25: =LN(J25/J24) -> 0.019418086 | ... AA25: =LN(N25/N24) -> 0.0053788874 | AD25: Amazon.com, Inc. (NASDAQGS:AMZN) | AE25: AMZN | AF25: =EXP(AVERAGE(RawData!Q13:Q766)*252)-1 -> 0.38989016 | AG25: =SLOPE(Q13:Q766,$AA$13:$AA$766) -> 1.2334674 | AH25: =$AE$20+AG25*($AE$21-$AE$20) -> 0.11279332
B26: 41297 | C26: 18.5555 | D26: 13.4055 | E26: 23.26 | F26: 213.6543 | G26: 64.9927 | H26: 51.756 | I26: 17.9475 | J26: 78.17 | K26: 0.3033 | L26: 70.69 | M26: 55.91 | N26: 149.37 | P26: =LN(C26/C25) -> 0.053503905 | Q26: =LN(D26/D25) -> -0.0077280712 | R26: =LN(E26/E25) -> -0.00042983022 | S26: =LN(F26/F25) -> -0.0030633435 | T26: =LN(G26/G25) -> -0.0019030174 | U26: =LN(H26/H25) -> -0.0042417061 | V26: =LN(I26/I25) -> -0.0026431121 | W26: =LN(J26/J25) -> 0.0021771155 | ... AA26: =LN(N26/N25) -> 0.0016080405 | AD26: BALL CORPORATION | AE26: BALL | AF26: =EXP(AVERAGE(RawData!R13:R766)*252)-1 -> 0.1650292 | AG26: =SLOPE(R13:R766,$AA$13:$AA$766) -> 0.3227183 | AH26: =$AE$20+AG26*($AE$21-$AE$20) -> 0.044942513
B27: 41298 | C27: 18.864 | D27: 13.681 | E27: 23.26 | F27: 214.0013 | G27: 64.9642 | H27: 52.226 | I27: 18.025 | J27: 78.02 | K27: 0.3048 | L27: 70.42 | M27: 56.22 | N27: 149.41 | P27: =LN(C27/C26) -> 0.016489103 | Q27: =LN(D27/D26) -> 0.020342938 | R27: =LN(E27/E26) -> 0 | S27: =LN(F27/F26) -> 0.0016228015 | T27: =LN(G27/G26) -> -0.00043860696 | U27: =LN(H27/H26) -> 0.0090400877 | V27: =LN(I27/I26) -> 0.0043088537 | W27: =LN(J27/J26) -> -0.0019207382 | ... AA27: =LN(N27/N26) -> 0.00026775554 | AD27: Equinix, Inc. (NASDAQGS:EQIX) | AE27: EQIX | AF27: =EXP(AVERAGE(RawData!S13:S766)*252)-1 -> 0.13491727 | AG27: =SLOPE(S13:S766,$AA$13:$AA$766) -> 0.98045838 | AH27: =$AE$20+AG27*($AE$21-$AE$20) -> 0.093944149
B28: 41299 | C28: 18.86 | D28: 14.1995 | E28: 23.305 | F28: 217.144 | G28: 65.0499 | H28: 51.942 | I28: 18.125 | J28: 79.51 | K28: 0.3103 | L28: 73.25 | M28: 56.04 | N28: 150.25 | P28: =LN(C28/C27) -> -0.00021206659 | Q28: =LN(D28/D27) -> 0.037198744 | R28: =LN(E28/E27) -> 0.0019327827 | S28: =LN(F28/F27) -> 0.014578638 | T28: =LN(G28/G27) -> 0.0013183187 | U28: =LN(H28/H27) -> -0.0054527437 | V28: =LN(I28/I27) -> 0.0055325176 | W28: =LN(J28/J27) -> 0.018917596 | ... AA28: =LN(N28/N27) -> 0.0056063686 | AD28: Honeywell International Inc. (NASDAQGS:HON) | AE28: HON | AF28: =EXP(AVERAGE(RawData!T13:T766)*252)-1 -> 0.16998015 | AG28: =SLOPE(T13:T766,$AA$13:$AA$766) -> 0.36078466 | AH28: =$AE$20+AG28*($AE$21-$AE$20) -> 0.047778457
B29: 41302 | C29: 18.7865 | D29: 13.802 | E29: 23.05 | F29: 214.6761 | G29: 65.6115 | H29: 51.412 | I29: 18.1 | J29: 79.28 | K29: 0.3153 | L29: 73.77 | M29: 55.81 | N29: 150.07 | P29: =LN(C29/C28) -> -0.0039047504 | Q29: =LN(D29/D28) -> -0.028393244 | R29: =LN(E29/E28) -> -0.01100216 | S29: =LN(F29/F28) -> -0.011430347 | T29: =LN(G29/G28) -> 0.0085963178 | U29: =LN(H29/H28) -> -0.010256103 | V29: =LN(I29/I28) -> -0.0013802625 | W29: =LN(J29/J28) -> -0.0028969099 | ... AA29: =LN(N29/N28) -> -0.0011987215 | AD29: Mastercard Incorporated (NYSE:MA) | AE29: MA | AF29: =EXP(AVERAGE(RawData!U13:U766)*252)-1 -> 0.24100898 | AG29: =SLOPE(U13:U766,$AA$13:$AA$766) -> 0.2974365 | AH29: =$AE$20+AG29*($AE$21-$AE$20) -> 0.043059019
B30: 41303 | C30: 18.8603 | D30: 13.0175 | E30: 23.11 | F30: 208.6607 | G30: 65.7734 | H30: 51.848 | I30: 18.1525 | J30: 79.95 | K30: 0.3085 | L30: 75 | M30: 56.28 | N30: 150.66 | P30: =LN(C30/C29) -> 0.003920657 | Q30: =LN(D30/D29) -> -0.058518903 | R30: =LN(E30/E29) -> 0.0025996548 | S30: =LN(F30/F29) -> -0.028420893 | T30: =LN(G30/G29) -> 0.0024645158 | U30: =LN(H30/H29) -> 0.0084447529 | V30: =LN(I30/I29) -> 0.002896354 | W30: =LN(J30/J29) -> 0.0084155493 | ... AA30: =LN(N30/N29) -> 0.0039237905 | AD30: NextEra Energy, Inc. (NYSE:NEE) | AE30: NEE | AF30: =EXP(AVERAGE(RawData!V13:V766)*252)-1 -> 0.13824544 | AG30: =SLOPE(V13:V766,$AA$13:$AA$766) -> 0.17850028 | AH30: =$AE$20+AG30*($AE$21-$AE$20) -> 0.034198271
B31: 41304 | C31: 18.864 | D31: 13.6382 | E31: 22.965 | F31: 206.6652 | G31: 65.3735 | H31: 51.6 | I31: 18 | J31: 78.6 | K31: 0.308 | L31: 75.08 | M31: 56.08 | N31: 150.07 | P31: =LN(C31/C30) -> 0.00019616004 | Q31: =LN(D31/D30) -> 0.046580073 | R31: =LN(E31/E30) -> -0.0062941065 | S31: =LN(F31/F30) -> -0.0096093952 | T31: =LN(G31/G30) -> -0.0060985237 | U31: =LN(H31/H30) -> -0.0047946886 | V31: =LN(I31/I30) -> -0.0084365344 | W31: =LN(J31/J30) -> -0.01702974 | ... AA31: =LN(N31/N30) -> -0.0039237905 | AD31: NRG Energy, Inc. (NYSE:NRG) | AE31: NRG | AF31: =EXP(AVERAGE(RawData!W13:W766)*252)-1 -> -0.0077837041 | AG31: =SLOPE(W13:W766,$AA$13:$AA$766) -> 0.41043154 | AH31: =$AE$20+AG31*($AE$21-$AE$20) -> 0.05147715
B32: 41305 | C32: 18.9106 | D32: 13.275 | E32: 22.26 | F32: 207.6774 | G32: 64.9642 | H32: 51.84 | I32: 18.0125 | J32: 78.05 | K32: 0.3065 | L32: 75.16 | M32: 55.21 | N32: 149.7 | P32: =LN(C32/C31) -> 0.0024672676 | Q32: =LN(D32/D31) -> -0.026992112 | R32: =LN(E32/E31) -> -0.031179972 | S32: =LN(F32/F31) -> 0.0048858216 | T32: =LN(G32/G31) -> -0.0062806286 | U32: =LN(H32/H31) -> 0.0046403796 | V32: =LN(I32/I31) -> 0.00069420343 | W32: =LN(J32/J31) -> -0.0070220525 | ... AA32: =LN(N32/N31) -> -0.0024685605 | AD32: NVIDIA Corporation (NASDAQGS:NVDA) | AE32: NVDA | AF32: =EXP(AVERAGE(RawData!X13:X766)*252)-1 -> 0.38066732 | AG32: =SLOPE(X13:X766,$AA$13:$AA$766) -> 1.1150478 | AH32: =$AE$20+AG32*($AE$21-$AE$20) -> 0.10397106
B33: 41306 | C33: 19.4088 | D33: 13.25 | E33: 22.795 | F33: 210.0392 | G33: 65.8305 | H33: 51.871 | I33: 18.07 | J33: 79.7 | K33: 0.3093 | L33: 75.92 | M33: 55.77 | N33: 151.24 | P33: =LN(C33/C32) -> 0.02600396 | Q33: =LN(D33/D32) -> -0.0018850147 | R33: =LN(E33/E32) -> 0.023749868 | S33: =LN(F33/F32) -> 0.011308266 | T33: =LN(G33/G32) -> 0.013246908 | U33: =LN(H33/H32) -> 0.0005978151 | V33: =LN(I33/I32) -> 0.0031871433 | W33: =LN(J33/J32) -> 0.020919939 | ... AA33: =LN(N33/N32) -> 0.010234688 | AD33: The Procter & Gamble Company (NYSE:PG) | AE33: PG | AF33: =EXP(AVERAGE(RawData!Y13:Y766)*252)-1 -> 0.046111307 | AG33: =SLOPE(Y13:Y766,$AA$13:$AA$766) -> 0.16737099 | AH33: =$AE$20+AG33*($AE$21-$AE$20) -> 0.033369139
B34: 41309 | C34: 18.9939 | D34: 12.999 | E34: 22.475 | F34: 207.0122 | G34: 65.2688 | H34: 51.422 | I34: 17.9975 | J34: 79.45 | K34: 0.304 | L34: 75.25 | M34: 55.75 | N34: 149.535 | P34: =LN(C34/C33) -> -0.021608696 | Q34: =LN(D34/D33) -> -0.019125121 | R34: =LN(E34/E33) -> -0.014137633 | S34: =LN(F34/F33) -> -0.014516451 | T34: =LN(G34/G33) -> -0.0085691295 | U34: =LN(H34/H33) -> -0.0086937707 | V34: =LN(I34/I33) -> -0.0040202452 | W34: =LN(J34/J33) -> -0.0031416928 | ... AA34: =LN(N34/N33) -> -0.0113375 | AD34: UnitedHealth Group Incorporated (NYSE:UNH) | AE34: UNH | AF34: =EXP(AVERAGE(RawData!Z13:Z766)*252)-1 -> 0.29293036 | AG34: =SLOPE(Z13:Z766,$AA$13:$AA$766) -> 0.2124334 | AH34: =$AE$20+AG34*($AE$21-$AE$20) -> 0.036726289
B35: 41310 | C35: 19.1621 | D35: 13.3445 | E35: 22.77 | F35: 210.6658 | G35: 66.5255 | H35: 52.069 | I35: 18.04 | J35: 80.16 | K35: 0.311 | L35: 75.7 | M35: 57.77 | N35: 151.05 | P35: =LN(C35/C34) -> 0.0088164949 | Q35: =LN(D35/D34) -> 0.026231884 | R35: =LN(E35/E34) -> 0.0130403 | S35: =LN(F35/F34) -> 0.017495263 | T35: =LN(G35/G34) -> 0.019071205 | U35: =LN(H35/H34) -> 0.012503666 | V35: =LN(I35/I34) -> 0.0023586553 | W35: =LN(J35/J34) -> 0.0088967444 | ... AA35: =LN(N35/N34) -> 0.010080429
B36: 41311 | C36: 19.2729 | D36: 13.111 | E36: 22.665 | F36: 210.1067 | G36: 66.5635 | H36: 52.355 | I36: 18.0025 | J36: 78.73 | K36: 0.3085 | L36: 76.15 | M36: 57.38 | N36: 151.16 | P36: =LN(C36/C35) -> 0.0057655942 | Q36: =LN(D36/D35) -> -0.017652742 | R36: =LN(E36/E35) -> -0.0046219957 | S36: =LN(F36/F35) -> -0.0026574946 | T36: =LN(G36/G35) -> 0.00057104646 | U36: =LN(H36/H35) -> 0.0054776817 | V36: =LN(I36/I35) -> -0.0020808775 | W36: =LN(J36/J35) -> -0.01800036 | ... AA36: =LN(N36/N35) -> 0.00072797065
B37: 41312 | C37: 19.3675 | D37: 13.0115 | E37: 22.605 | F37: 206.376 | G37: 66.9919 | H37: 51.955 | I37: 18.0625 | J37: 78 | K37: 0.3073 | L37: 76.15 | M37: 57.05 | N37: 150.96 | P37: =LN(C37/C36) -> 0.0048964394 | Q37: =LN(D37/D36) -> -0.0076179907 | R37: =LN(E37/E36) -> -0.0026507636 | S37: =LN(F37/F36) -> -0.017915749 | T37: =LN(G37/G36) -> 0.0064153373 | U37: =LN(H37/H36) -> -0.0076694844 | V37: =LN(I37/I36) -> 0.0033273287 | W37: =LN(J37/J36) -> -0.0093154505 | ... AA37: =LN(N37/N36) -> -0.0013239774
B38: 41313 | C38: 19.6533 | D38: 13.0975 | E38: 22.68 | F38: 211.8034 | G38: 67.1443 | H38: 52.447 | I38: 18.025 | J38: 79.07 | K38: 0.3093 | L38: 75.75 | M38: 57.74 | N38: 151.8 | P38: =LN(C38/C37) -> 0.01464886 | Q38: =LN(D38/D37) -> 0.0065877905 | R38: =LN(E38/E37) -> 0.0033123581 | S38: =LN(F38/F37) -> 0.025958738 | T38: =LN(G38/G37) -> 0.0022723182 | U38: =LN(H38/H37) -> 0.0094251766 | V38: =LN(I38/I37) -> -0.0020782827 | W38: =LN(J38/J37) -> 0.013624709 | ... AA38: =LN(N38/N37) -> 0.0055489639
B39: 41316 | C39: 19.5795 | D39: 12.8605 | E39: 22.57 | F39: 210.1838 | G39: 66.7254 | H39: 52.085 | I39: 18.045 | J39: 77.93 | K39: 0.3128 | L39: 75.81 | M39: 57.12 | N39: 151.77 | P39: =LN(C39/C38) -> -0.0037621626 | Q39: =LN(D39/D38) -> -0.018260774 | R39: =LN(E39/E38) -> -0.004861888 | S39: =LN(F39/F38) -> -0.0076760999 | T39: =LN(G39/G38) -> -0.0062583448 | U39: =LN(H39/H38) -> -0.0069261364 | V39: =LN(I39/I38) -> 0.0011089549 | W39: =LN(J39/J38) -> -0.014522548 | ... AA39: =LN(N39/N38) -> -0.00019764799
B40: 41317 | C40: 19.5364 | D40: 12.935 | E40: 22.445 | F40: 206.8098 | G40: 67.0395 | H40: 51.964 | I40: 18.1225 | J40: 78.53 | K40: 0.3108 | L40: 75.98 | M40: 57.01 | N40: 152.02 | P40: =LN(C40/C39) -> -0.0022037083 | Q40: =LN(D40/D39) -> 0.0057762173 | R40: =LN(E40/E39) -> -0.0055537186 | S40: =LN(F40/F39) -> -0.016182856 | T40: =LN(G40/G39) -> 0.0046963079 | U40: =LN(H40/H39) -> -0.0023258283 | V40: =LN(I40/I39) -> 0.0042856221 | W40: =LN(J40/J39) -> 0.0076697295 | ... AA40: =LN(N40/N39) -> 0.0016458742
...

Sheet Efficient Frontier
O1: Risk-fee rate | P1: 0.0209
B2: Ticker | C2: GOOGL | D2: AMZN | E2: BALL | F2: EQIX | G2: HON | H2: MA | I2: NEE | J2: SLB | K2: NVDA | L2: PG | M2: UNH | O2: Market Return | P2: 0.0954 | X2: Ticker | Y2: Weight
B3: Historical ER | C3: =EXP(AVERAGE(RawData!P13:P766)*252)-1 -> 0.29818694 | D3: =EXP(AVERAGE(RawData!Q13:Q766)*252)-1 -> 0.38989016 | E3: =EXP(AVERAGE(RawData!R13:R766)*252)-1 -> 0.1650292 | F3: =EXP(AVERAGE(RawData!S13:S766)*252)-1 -> 0.13491727 | G3: =EXP(AVERAGE(RawData!T13:T766)*252)-1 -> 0.16998015 | H3: =EXP(AVERAGE(RawData!U13:U766)*252)-1 -> 0.24100898 | I3: =EXP(AVERAGE(RawData!V13:V766)*252)-1 -> 0.13824544 | J3: =EXP(AVERAGE(RawData!W13:W766)*252)-1 -> -0.0077837041 | ... M3: =EXP(AVERAGE(RawData!Z13:Z766)*252)-1 -> 0.29293036 | X3: EQIX | Y3: 0.02
B4: CAPM ER | C4: 0.102105 | D4: 0.11328 | E4: 0.08795 | F4: 0.093165 | G4: 0.105085 | H4: 0.11179 | I4: 0.07007 | J4: 0.102105 | K4: 0.10583 | L4: 0.070815 | M4: 0.09242 | X4: SLB | Y4: 0.02
B5: Blend Return | C5: =0.6*C4+0.4*C3 -> 0.18053778 | D5: =0.6*D4+0.4*D3 -> 0.22392407 | E5: =0.6*E4+0.4*E3 -> 0.11878168 | F5: =0.6*F4+0.4*F3 -> 0.10986591 | G5: =0.6*G4+0.4*G3 -> 0.13104306 | H5: =0.6*H4+0.4*H3 -> 0.16347759 | I5: =0.6*I4+0.4*I3 -> 0.097340177 | J5: =0.6*J4+0.4*J3 -> 0.058149518 | ... M5: =0.6*M4+0.4*M3 -> 0.17262414 | X5: PG | Y5: 0.03812955
B6: Standard Deviation | C6: =SQRT(_xlfn.VAR.S(RawData!P13:P766)*252) -> 0.23789632 | D6: =SQRT(_xlfn.VAR.S(RawData!Q13:Q766)*252) -> 0.30987886 | E6: =SQRT(_xlfn.VAR.S(RawData!R13:R766)*252) -> 0.19599512 | F6: =SQRT(_xlfn.VAR.S(RawData!S13:S766)*252) -> 0.2355939 | G6: =SQRT(_xlfn.VAR.S(RawData!T13:T766)*252) -> 0.17544579 | H6: =SQRT(_xlfn.VAR.S(RawData!U13:U766)*252) -> 0.21116092 | I6: =SQRT(_xlfn.VAR.S(RawData!V13:V766)*252) -> 0.16711131 | J6: =SQRT(_xlfn.VAR.S(RawData!W13:W766)*252) -> 0.23352439 | ... M6: =SQRT(_xlfn.VAR.S(RawData!Z13:Z766)*252) -> 0.21800442 | X6: NEE | Y6: 0.05
B7: Min weight | C7: 0.02 | D7: 0.02 | E7: 0.02 | F7: 0.02 | G7: 0.02 | H7: 0.02 | I7: 0.02 | J7: 0.02 | K7: 0.02 | L7: 0.02 | M7: 0.02 | X7: BALL | Y7: 0.05
B8: Max Weight | C8: 0.25 | D8: 0.25 | E8: 0.05 | F8: 0.1 | G8: 0.1 | H8: 0.1 | I8: 0.05 | J8: 0.05 | K8: 0.25 | L8: 0.05 | M8: 0.1 | X8: HON | Y8: 0.1
B9: Weight | C9: 0.17305068 | D9: 0.12958581 | E9: 0.05 | F9: 0.02 | G9: 0.1 | H9: 0.1 | I9: 0.05 | J9: 0.02 | K9: 0.21923422 | L9: 0.03812955 | M9: 0.1 | N9: TOTAL | X9: MA | Y9: 0.1
B10: USD | C10: =100000*C9 -> 17305.068 | D10: =100000*D9 -> 12958.581 | E10: =100000*E9 -> 5000 | F10: =100000*F9 -> 2000 | G10: =100000*G9 -> 10000 | H10: =100000*H9 -> 10000 | I10: =100000*I9 -> 5000 | J10: =100000*J9 -> 2000 | ... M10: =100000*M9 -> 10000 | N10: =SUM(C10:M10) -> 100000.03 | X10: UNH | Y10: 0.1
B11: Random Array | C11: =RAND() -> 0.42667114 | D11: =RAND() -> 0.10073756 | E11: =RAND() -> 0.67356505 | F11: =RAND() -> 0.3144865 | G11: =RAND() -> 0.99364414 | H11: =RAND() -> 0.7517759 | I11: =RAND() -> 0.97242474 | J11: =RAND() -> 0.37474264 | ... M11: =RAND() -> 0.56465149 | N11: =SUM(C11:M11) -> 6.0600006 | X11: AMZN | Y11: 0.12958581
X12: GOOGL | Y12: 0.17305068
B13: Portfolio Summary | X13: NVDA | Y13: 0.21923422
B14: Expected Return | C14: =SUMPRODUCT(C5:M5,C9:M9) -> 0.17076687
B15: Standard Deviation | C15: {=SQRT(MMULT(MMULT(C9:M9,C22:M32),TRANSPOSE(C9:M9)*252))} -> 0.13673793
B16: Risk Free | C16: 0.0209
B17: Total Weight | C17: =SUM(C9:M9) -> 1.0000003
B18: Sharpe Ratio | C18: =(C14-C16)/C15 -> 1.0960154
B20: Covariance Matrix
C21: GOOGL | D21: AMZN | E21: BALL | F21: EQIX | G21: HON | H21: MA | I21: NEE | J21: SLB | K21: NVDA | L21: PG | M21: UNH | N21: SPY
B22: GOOGL | C22: =VARP(RawData!$P$13:$P$766) -> 0.00022428413 | D22: {=TRANSPOSE(C23:C33)} -> 0.00014843626 | E22: 1.7238044e-05 | F22: 7.4285768e-05 | G22: 2.3077031e-05 | H22: 2.7015478e-05 | I22: 7.4534545e-06 | J22: 3.05013e-05 | K22: 8.5089582e-05 | L22: 7.2690228e-06 | M22: 7.9761036e-06 | N22: 6.9841368e-05
B23: AMZN | C23: 0.00014843626 | D23: =VARP(RawData!$Q$13:$Q$766) -> 0.00038054585 | E23: {=TRANSPOSE(D24:D33)} -> 3.6144937e-05 | F23: 9.2291981e-05 | G23: 3.3215985e-05 | H23: 3.5706443e-05 | I23: 3.9982461e-06 | J23: 3.8823368e-05 | K23: 9.1508276e-05 | L23: 1.3932236e-06 | M23: 9.8104194e-06 | N23: 7.967713e-05
B24: BALL | C24: 1.7238044e-05 | D24: 3.6144937e-05 | E24: =VARP(RawData!$R$13:$R$766) -> 0.00015223469 | F24: {=TRANSPOSE(E25:E33)} -> 2.6090872e-05 | G24: 7.2266724e-05 | H24: 6.1380852e-05 | I24: 4.3607741e-05 | J24: 6.7775989e-05 | K24: 3.0594719e-05 | L24: 4.0187215e-05 | M24: 6.0956829e-05 | N24: 2.0846329e-05
B25: EQIX | C25: 7.4285768e-05 | D25: 9.2291981e-05 | E25: 2.6090872e-05 | F25: =VARP(RawData!$S$13:$S$766) -> 0.00021996378 | G25: {=TRANSPOSE(F26:F33)} -> 2.0531455e-05 | H25: 2.0287794e-05 | I25: 1.195097e-05 | J25: 2.5279524e-05 | K25: 7.6259769e-05 | L25: 1.3192323e-05 | M25: 1.3113014e-05 | N25: 6.3333744e-05
B26: HON | C26: 2.3077031e-05 | D26: 3.3215985e-05 | E26: 7.2266724e-05 | F26: 2.0531455e-05 | G26: =VARP(RawData!$T$13:$T$766) -> 0.00012198572 | H26: {=TRANSPOSE(G27:G33)} -> 8.7705436e-05 | I26: 5.209718e-05 | J26: 7.7179593e-05 | K26: 2.8323963e-05 | L26: 4.629761e-05 | M26: 6.6646217e-05 | N26: 2.3305266e-05
B27: MA | C27: 2.7015478e-05 | D27: 3.5706443e-05 | E27: 6.1380852e-05 | F27: 2.0287794e-05 | G27: 8.7705436e-05 | H27: =VARP(RawData!$U$13:$U$766) -> 0.00017670554 | I27: {=TRANSPOSE(H28:H33)} -> 4.9114471e-05 | J27: 7.0437657e-05 | K27: 2.6928169e-05 | L27: 5.2562844e-05 | M27: 7.2141514e-05 | N27: 1.9213225e-05
B28: NEE | C28: 7.4534545e-06 | D28: 3.9982461e-06 | E28: 4.3607741e-05 | F28: 1.195097e-05 | G28: 5.209718e-05 | H28: 4.9114471e-05 | I28: =VARP(RawData!$V$13:$V$766) -> 0.00011067124 | J28: {=TRANSPOSE(I29:I33)} -> 4.1352675e-05 | K28: 1.4331214e-05 | L28: 3.8380142e-05 | M28: 3.646059e-05 | N28: 1.1530414e-05
B29: SLB | C29: 3.05013e-05 | D29: 3.8823368e-05 | E29: 6.7775989e-05 | F29: 2.5279524e-05 | G29: 7.7179593e-05 | H29: 7.0437657e-05 | I29: 4.1352675e-05 | J29: =VARP(RawData!$W$13:$W$766) -> 0.00021611632 | K29: {=TRANSPOSE(J30:J33)} -> 3.4549058e-05 | L29: 3.2858952e-05 | M29: 5.5961919e-05 | N29: 2.6512259e-05
B30: NVDA | C30: 8.5089582e-05 | D30: 9.1508276e-05 | E30: 3.0594719e-05 | F30: 7.6259769e-05 | G30: 2.8323963e-05 | H30: 2.6928169e-05 | I30: 1.4331214e-05 | J30: 3.4549058e-05 | K30: =VARP(RawData!$X$13:$X$766) -> 0.00029539865 | L30: {=TRANSPOSE(K31:K33)} -> 1.3366626e-05 | M30: 1.7326505e-05 | N30: 7.2027687e-05
B31: PG | C31: 7.2690228e-06 | D31: 1.3932236e-06 | E31: 4.0187215e-05 | F31: 1.3192323e-05 | G31: 4.629761e-05 | H31: 5.2562844e-05 | I31: 3.8380142e-05 | J31: 3.2858952e-05 | K31: 1.3366626e-05 | L31: =VARP(RawData!$Y$13:$Y$766) -> 8.843362e-05 | M31: {=TRANSPOSE(L32:L33)} -> 4.3671157e-05 | N31: 1.0811506e-05
B32: UNH | C32: 7.9761036e-06 | D32: 9.8104194e-06 | E32: 6.0956829e-05 | F32: 1.3113014e-05 | G32: 6.6646217e-05 | H32: 7.2141514e-05 | I32: 3.646059e-05 | J32: 5.5961919e-05 | K32: 1.7326505e-05 | L32: 4.3671157e-05 | M32: =VARP(RawData!$Z$13:$Z$766) -> 0.00018834482 | N32: {=TRANSPOSE(M33:M33)} -> 1.372236e-05
B33: SPY | C33: 6.9841368e-05 | D33: 7.967713e-05 | E33: 2.0846329e-05 | F33: 6.3333744e-05 | G33: 2.3305266e-05 | H33: 1.9213225e-05 | I33: 1.1530414e-05 | J33: 2.6512259e-05 | K33: 7.2027687e-05 | L33: 1.0811506e-05 | M33: 1.372236e-05 | N33: =VARP(RawData!$AA$13:$AA$766) -> 6.4596056e-05
C36: Portfolio SD | D36: Portfolio Return
B37: Simulation | C37: =C15 -> 0.13673793 | D37: =C14 -> 0.17076687
B38: 1 | C38: 0.1236783 | D38: 0.1303266
B39: 2 | C39: 0.12085936 | D39: 0.13292002
B40: 3 | C40: 0.11960483 | D40: 0.11341976
B41: 4 | C41: 0.13482581 | D41: 0.14672747
B42: 5 | C42: 0.12514363 | D42: 0.12676619
B43: 6 | C43: 0.12582824 | D43: 0.14388691
...

Sheet Final Order
B4: Ticker | C4: Historical ER | D4: CAPM ER | E4: Blended ER | F4: Standard Deviation | G4: Min Weight | H4: Max Weight | I4: Final Weight | J4: USD | K4: Price | L4: Quantity | M4: Total
B5: NVDA | C5: 0.3807 | D5: 0.1058 | E5: 0.2158 | F5: 0.273 | G5: 0.02 | H5: 0.25 | I5: 0.2192 | J5: =I5*100000 -> 21920 | K5: 159.34 | L5: =ROUNDDOWN(J5/K5,0) -> 137 | M5: =L5*K5 -> 21829.58
B6: GOOGL | C6: 0.2982 | D6: 0.1021 | E6: 0.1805 | F6: 0.2379 | G6: 0.02 | H6: 0.25 | I6: 0.1731 | J6: =I6*100000 -> 17310 | K6: 179.53 | L6: =ROUNDDOWN(J6/K6,0) -> 96 | M6: =L6*K6 -> 17234.88
B7: AMZN | C7: 0.3899 | D7: 0.1133 | E7: 0.2239 | F7: 0.3099 | G7: 0.02 | H7: 0.25 | I7: 0.1296 | J7: =I7*100000 -> 12960 | K7: 223.41 | L7: =ROUNDDOWN(J7/K7,0) -> 58 | M7: =L7*K7 -> 12957.78
B8: HON | C8: 0.17 | D8: 0.1051 | E8: 0.131 | F8: 0.1754 | G8: 0.02 | H8: 0.1 | I8: 0.1 | J8: =I8*100000 -> 10000 | K8: 240.4 | L8: =ROUNDDOWN(J8/K8,0) -> 41 | M8: =L8*K8 -> 9856.4
B9: MA | C9: 0.241 | D9: 0.1118 | E9: 0.1635 | F9: 0.2112 | G9: 0.02 | H9: 0.1 | I9: 0.1 | J9: =I9*100000 -> 10000 | K9: 569.24 | L9: =ROUNDDOWN(J9/K9,0) -> 17 | M9: =L9*K9 -> 9677.08
B10: UNH | C10: 0.2929 | D10: 0.0924 | E10: 0.1726 | F10: 0.218 | G10: 0.02 | H10: 0.1 | I10: 0.1 | J10: =I10*100000 -> 10000 | K10: 308.55 | L10: =ROUNDDOWN(J10/K10,0) -> 32 | M10: =L10*K10 -> 9873.6
B11: BALL | C11: 0.165 | D11: 0.088 | E11: 0.1188 | F11: 0.196 | G11: 0.02 | H11: 0.05 | I11: 0.05 | J11: =I11*100000 -> 5000 | K11: 58.73 | L11: =ROUNDDOWN(J11/K11,0) -> 85 | M11: =L11*K11 -> 4992.05
B12: NEE | C12: 0.1382 | D12: 0.0701 | E12: 0.0973 | F12: 0.1671 | G12: 0.02 | H12: 0.05 | I12: 0.05 | J12: =I12*100000 -> 5000 | K12: 73.88 | L12: =ROUNDDOWN(J12/K12,0) -> 67 | M12: =L12*K12 -> 4949.96
B13: PG | C13: 0.0461 | D13: 0.0708 | E13: 0.0609 | F13: 0.1494 | G13: 0.02 | H13: 0.05 | I13: 0.0381 | J13: =I13*100000 -> 3810 | K13: 160.83 | L13: =ROUNDDOWN(J13/K13,0) -> 23 | M13: =L13*K13 -> 3699.09
B14: EQIX | C14: 0.1349 | D14: 0.0932 | E14: 0.1099 | F14: 0.2356 | G14: 0.02 | H14: 0.1 | I14: 0.02 | J14: =I14*100000 -> 2000 | K14: 787 | L14: =ROUNDDOWN(J14/K14,0) -> 2 | M14: =L14*K14 -> 1574
B15: SLB | C15: -0.0078 | D15: 0.1021 | E15: 0.0581 | F15: 0.2335 | G15: 0.02 | H15: 0.05 | I15: 0.02 | J15: =I15*100000 -> 2000 | K15: 35.65 | L15: =ROUNDDOWN(J15/K15,0) -> 56 | M15: =L15*K15 -> 1996.4
H16: TOTAL | I16: 1 | J16: =SUM(J5:J15) -> 100000 | L16: =SUM(L5:L15) -> 614 | M16: =SUM(M5:M15) -> 98640.82

Sheet Sheet9
B3: MTCAX | C3: Year | D3: Q1 | E3: Q2 | F3: Q3 | G3: Q4 | H3: Return | I3: Year
C4: 2015 | D4: 0.0148 | E4: 0.0093 | F4: -0.0236 | G4: 0.1037 | H4: =(1 + D6)*(1 + E6)*(1 + F6)*(1 + G6)-1 -> 0.35250667 | I4: 2013
C5: 2014 | D5: 0.0127 | E5: 0.0168 | F5: 0.0204 | G5: 0.0501 | H5: =(1 + D5)*(1 + E5)*(1 + F5)*(1 + G5)-1 -> 0.10336056 | I5: 2014
C6: 2013 | D6: 0.0609 | E6: 0.024 | F6: 0.1111 | G6: 0.1205 | H6: =(1 + D4)*(1 + E4)*(1 + F4)*(1 + G4)-1 -> 0.10377244 | I6: 2015
B8: PRGTX | C8: Year | D8: Q1 | E8: Q2 | F8: Q3 | G8: Q4
C9: 2015 | D9: 0.0414 | E9: 0.0398 | F9: -0.0315 | G9: 0.1543 | H9: =(1 + D11)*(1 + E11)*(1 + F11)*(1 + G11)-1 -> 0.39925018
C10: 2014 | D10: 0.0636 | E10: 0.0945 | F10: 0.029 | G10: 0.035 | H10: =(1 + D10)*(1 + E10)*(1 + F10)*(1 + G10)-1 -> 0.23979482
C11: 2013 | D11: 0.0415 | E11: 0.0313 | F11: 0.15 | G11: 0.1328 | H11: =(1 + D9)*(1 + E9)*(1 + F9)*(1 + G9)-1 -> 0.21055829

Sheet Rawdata2
A1: Dates
A2: Start Date | B2: 42005
A3: End | B3: 42369
A4: Interval | B4: 2
B9: Company | C9: #VALUE! | D9: #VALUE! | E9: BALL CORPORATION (XNYS:BALL) | F9: #VALUE! | G9: #VALUE! | H9: #VALUE! | I9: #VALUE! | J9: #VALUE! | K9: #VALUE! | L9: #VALUE! | M9: #VALUE! | O9: RETURNS
B10: Ticker | C10: GOOGL | D10: AMZN | E10: BALL | F10: EQIX | G10: HON | H10: MA | I10: NEE | J10: SLB | K10: NVDA | L10: PG | M10: UNH | N10: Ticker | O10: GOOGL | P10: AMZN | Q10: BALL | R10: EQIX | S10: HON | T10: MA | U10: NEE | V10: SLB | W10: NVDA | X10: PG | Y10: UNH
B11: {=_xlfn.STOCKHISTORY(C10,B2,B3,0,1,0,1)} -> Date | C11: Close | D11: {=_xlfn.STOCKHISTORY(D10,$B$2,$B$3,0,1,1)} -> Close | E11: {=_xlfn.STOCKHISTORY(E10,$B$2,$B$3,0,1,1)} -> Close | F11: {=_xlfn.STOCKHISTORY(F10,$B$2,$B$3,0,1,1)} -> Close | G11: {=_xlfn.STOCKHISTORY(G10,$B$2,$B$3,0,1,1)} -> Close | H11: {=_xlfn.STOCKHISTORY(H10,$B$2,$B$3,0,1,1)} -> Close | I11: {=_xlfn.STOCKHISTORY(I10,$B$2,$B$3,0,1,1)} -> Close | J11: {=_xlfn.STOCKHISTORY(J10,$B$2,$B$3,0,1,1)} -> Close | K11: {=_xlfn.STOCKHISTORY(K10,$B$2,$B$3,0,1,1)} -> Close | ... M11: {=_xlfn.STOCKHISTORY(M10,$B$2,$B$3,0,1,1)} -> Close
B12: 42006 | C12: 26.4775 | D12: 15.426 | E12: 34.155 | F12: 220.1565 | G12: 95.4185 | H12: 85.68 | I12: 26.6725 | J12: 85.67 | K12: 0.5033 | L12: 90.44 | M12: 100.78 | O12: GOOGL | P12: AMZN | Q12: BALL | R12: EQIX | S12: HON | T12: MA | U12: NEE | V12: SLB | W12: NVDA | X12: PG | Y12: UNH
B13: 42009 | C13: 25.973 | D13: 15.1095 | E13: 33.41 | F13: 217.8932 | G13: 93.6002 | H13: 83.27 | I13: 26.39 | J13: 83.35 | K13: 0.4948 | L13: 90.01 | M13: 99.12 | O13: =(C13-C12)/C12 -> -0.019053914 | P13: =(D13-D12)/D12 -> -0.020517308 | Q13: =(E13-E12)/E12 -> -0.021812326 | R13: =(F13-F12)/F12 -> -0.010280414 | S13: =(G13-G12)/G12 -> -0.019056053 | T13: =(H13-H12)/H12 -> -0.028127918 | U13: =(I13-I12)/I12 -> -0.010591433 | V13: =(J13-J12)/J12 -> -0.027080658 | ... Y13: =(M13-M12)/M12 -> -0.016471522
B14: 42010 | C14: 25.332 | D14: 14.7645 | E14: 32.845 | F14: 213.1433 | G14: 93.3813 | H14: 83.09 | I14: 26.4925 | J14: 81.72 | K14: 0.4798 | L14: 89.6 | M14: 98.92 | O14: =(C14-C13)/C13 -> -0.024679475 | P14: =(D14-D13)/D13 -> -0.022833317 | Q14: =(E14-E13)/E13 -> -0.016911104 | R14: =(F14-F13)/F13 -> -0.021799212 | S14: =(G14-G13)/G13 -> -0.0023386702 | T14: =(H14-H13)/H13 -> -0.0021616428 | U14: =(I14-I13)/I13 -> 0.003884047 | V14: =(J14-J13)/J13 -> -0.019556089 | ... Y14: =(M14-M13)/M13 -> -0.0020177563
B15: 42011 | C15: 25.2575 | D15: 14.921 | E15: 33.135 | F15: 213.8427 | G15: 94.0572 | H15: 84.22 | I15: 26.735 | J15: 81.71 | K15: 0.4784 | L15: 90.07 | M15: 99.93 | O15: =(C15-C14)/C14 -> -0.0029409443 | P15: =(D15-D14)/D14 -> 0.010599749 | Q15: =(E15-E14)/E14 -> 0.00882935 | R15: =(F15-F14)/F14 -> 0.0032813605 | S15: =(G15-G14)/G14 -> 0.0072380659 | T15: =(H15-H14)/H14 -> 0.013599711 | U15: =(I15-I14)/I14 -> 0.009153534 | V15: =(J15-J14)/J14 -> -0.00012236907 | ... Y15: =(M15-M14)/M14 -> 0.010210271
B16: 42012 | C16: 25.3455 | D16: 15.023 | E16: 33.705 | F16: 216.3974 | G16: 95.7708 | H16: 85.53 | I16: 26.8975 | J16: 82.7 | K16: 0.4965 | L16: 91.1 | M16: 104.7 | O16: =(C16-C15)/C15 -> 0.0034841136 | P16: =(D16-D15)/D15 -> 0.0068360029 | Q16: =(E16-E15)/E15 -> 0.017202354 | R16: =(F16-F15)/F15 -> 0.011946632 | S16: =(G16-G15)/G15 -> 0.018218701 | T16: =(H16-H15)/H15 -> 0.0155545 | U16: =(I16-I15)/I15 -> 0.0060781747 | V16: =(J16-J15)/J15 -> 0.01211602 | ... Y16: =(M16-M15)/M15 -> 0.047733413
B17: 42013 | C17: 25.036 | D17: 14.8465 | E17: 33.04 | F17: 210.6761 | G17: 94.1809 | H17: 84.44 | I17: 26.66 | J17: 81.22 | K17: 0.4985 | L17: 90.25 | M17: 103.72 | O17: =(C17-C16)/C16 -> -0.012211241 | P17: =(D17-D16)/D16 -> -0.011748652 | Q17: =(E17-E16)/E16 -> -0.01973001 | R17: =(F17-F16)/F16 -> -0.026438857 | S17: =(G17-G16)/G16 -> -0.016601093 | T17: =(H17-H16)/H16 -> -0.012744066 | U17: =(I17-I16)/I16 -> -0.0088298169 | V17: =(J17-J16)/J16 -> -0.01789601 | ... Y17: =(M17-M16)/M16 -> -0.0093600764
B18: 42016 | C18: 24.853 | D18: 14.5705 | E18: 32.895 | F18: 210.6664 | G18: 93.724 | H18: 83.36 | I18: 26.5925 | J18: 78.05 | K18: 0.4923 | L18: 89.92 | M18: 102.55 | O18: =(C18-C17)/C17 -> -0.0073094744 | P18: =(D18-D17)/D17 -> -0.01859024 | Q18: =(E18-E17)/E17 -> -0.0043886199 | R18: =(F18-F17)/F17 -> -4.6042242e-05 | S18: =(G18-G17)/G17 -> -0.0048513021 | T18: =(H18-H17)/H17 -> -0.012790147 | U18: =(I18-I17)/I17 -> -0.002531883 | V18: =(J18-J17)/J17 -> -0.039029796 | ... Y18: =(M18-M17)/M17 -> -0.01128037
B19: 42017 | C19: 25.09 | D19: 14.737 | E19: 32.735 | F19: 211.0258 | G19: 94.3904 | H19: 83.55 | I19: 26.6975 | J19: 77.78 | K19: 0.4914 | L19: 90.3 | M19: 103.07 | O19: =(C19-C18)/C18 -> 0.0095360721 | P19: =(D19-D18)/D18 -> 0.011427199 | Q19: =(E19-E18)/E18 -> -0.0048639611 | R19: =(F19-F18)/F18 -> 0.0017060148 | S19: =(G19-G18)/G18 -> 0.0071102386 | T19: =(H19-H18)/H18 -> 0.0022792706 | U19: =(I19-I18)/I18 -> 0.0039484817 | V19: =(J19-J18)/J18 -> -0.0034593209 | ... Y19: =(M19-M18)/M18 -> 0.0050706972
B20: 42018 | C20: 25.2965 | D20: 14.6635 | E20: 32.75 | F20: 212.6091 | G20: 93.9525 | H20: 83.46 | I20: 26.8625 | J20: 78.39 | K20: 0.4935 | L20: 89.99 | M20: 103.33 | O20: =(C20-C19)/C19 -> 0.0082303707 | P20: =(D20-D19)/D19 -> -0.0049874466 | Q20: =(E20-E19)/E19 -> 0.00045822514 | R20: =(F20-F19)/F19 -> 0.0075028741 | S20: =(G20-G19)/G19 -> -0.004639243 | T20: =(H20-H19)/H19 -> -0.0010771993 | U20: =(I20-I19)/I19 -> 0.006180354 | V20: =(J20-J19)/J19 -> 0.0078426331 | ... Y20: =(M20-M19)/M19 -> 0.0025225575
B21: 42019 | C21: 25.2005 | D21: 14.3475 | E21: 32.48 | F21: 211.9583 | G21: 92.4483 | H21: 82.25 | I21: 26.76 | J21: 76.63 | K21: 0.49 | L21: 89.86 | M21: 104.46 | O21: =(C21-C20)/C20 -> -0.0037949914 | P21: =(D21-D20)/D20 -> -0.021550107 | Q21: =(E21-E20)/E20 -> -0.0082442748 | R21: =(F21-F20)/F20 -> -0.0030610167 | S21: =(G21-G20)/G20 -> -0.016010218 | T21: =(H21-H20)/H20 -> -0.014497963 | U21: =(I21-I20)/I20 -> -0.0038157282 | V21: =(J21-J20)/J20 -> -0.022451843 | ... Y21: =(M21-M20)/M20 -> 0.010935837
B22: 42020 | C22: 25.5228 | D22: 14.537 | E22: 32.435 | F22: 213.9301 | G22: 93.505 | H22: 83.8 | I22: 27.055 | J22: 81.33 | K22: 0.499 | L22: 91.25 | M22: 105.77 | O22: =(C22-C21)/C21 -> 0.012789429 | P22: =(D22-D21)/D21 -> 0.013207876 | Q22: =(E22-E21)/E21 -> -0.001385468 | R22: =(F22-F21)/F21 -> 0.0093027732 | S22: =(G22-G21)/G21 -> 0.011430172 | T22: =(H22-H21)/H21 -> 0.018844985 | U22: =(I22-I21)/I21 -> 0.011023916 | V22: =(J22-J21)/J21 -> 0.061333681 | ... Y22: =(M22-M21)/M21 -> 0.012540685
B23: 42024 | C23: 25.497 | D23: 14.472 | E23: 32.39 | F23: 216.0282 | G23: 94.2285 | H23: 84.26 | I23: 27.2325 | J23: 80.48 | K23: 0.5005 | L23: 91.19 | M23: 105.62 | O23: =(C23-C22)/C22 -> -0.0010108609 | P23: =(D23-D22)/D22 -> -0.004471349 | Q23: =(E23-E22)/E22 -> -0.0013873902 | R23: =(F23-F22)/F22 -> 0.0098074091 | S23: =(G23-G22)/G22 -> 0.0077375541 | T23: =(H23-H22)/H22 -> 0.0054892601 | U23: =(I23-I22)/I22 -> 0.0065607097 | V23: =(J23-J22)/J22 -> -0.010451248 | ... Y23: =(M23-M22)/M22 -> -0.0014181715
B24: 42025 | C24: 26.0195 | D24: 14.8625 | E24: 32.68 | F24: 217.019 | G24: 94.4856 | H24: 83.72 | I24: 27.4725 | J24: 82.21 | K24: 0.5075 | L24: 90.73 | M24: 109.32 | O24: =(C24-C23)/C23 -> 0.020492607 | P24: =(D24-D23)/D23 -> 0.02698314 | Q24: =(E24-E23)/E23 -> 0.0089533807 | R24: =(F24-F23)/F23 -> 0.0045864383 | S24: =(G24-G23)/G23 -> 0.0027284739 | T24: =(H24-H23)/H23 -> -0.0064087349 | U24: =(I24-I23)/I23 -> 0.0088129992 | V24: =(J24-J23)/J23 -> 0.021496024 | ... Y24: =(M24-M23)/M23 -> 0.035031244
... B263: 42369 | C263: 38.9005 | D263: 33.7945 | E263: 36.365 | F263: 302.4 | G263: 98.5982 | H263: 97.36 | I263: 25.9725 | J263: 69.75 | K263: 0.824 | L263: 79.41 | M263: 117.64 | O263: =(C263-C262)/C262 -> -0.015551057 | P263: =(D263-D262)/D262 -> -0.019127229 | Q263: =(E263-E262)/E262 -> -0.0081821901 | R263: =(F263-F262)/F262 -> -0.00095807592 | S263: =(G263-G262)/G262 -> -0.0085202448 | T263: =(H263-H262)/H262 -> -0.01527258 | U263: =(I263-I262)/I262 -> -0.0097226194 | V263: =(J263-J262)/J262 -> 0.001579552 | ... Y263: =(M263-M262)/M262 -> -0.010763539

Sheet SD
A1: Dates
A2: Start Date | B2: 40544
A3: End | B3: 42735
A4: Interval | B4: 2
B9: Company | C9: #VALUE! | E9: #VALUE! | G9: BALL CORPORATION (XNYS:BALL) | I9: #VALUE! | K9: #VALUE! | M9: #VALUE! | O9: #VALUE! | Q9: #VALUE! | S9: #VALUE! | U9: #VALUE! | W9: #VALUE!
B10: Ticker | C10: GOOGL | E10: AMZN | G10: BALL | I10: EQIX | K10: HON | M10: MA | O10: NEE | Q10: SLB | S10: NVDA | U10: PG | W10: UNH
B12: {=_xlfn.STOCKHISTORY(C10,B2,B3,2,1,0,1)} -> Date | C12: Close | D12: Return | E12: {=_xlfn.STOCKHISTORY(E10,$B$2,$B$3,2,1,1)} -> Close | F12: Return | G12: {=_xlfn.STOCKHISTORY(G10,$B$2,$B$3,2,1,1)} -> Close | H12: Return | I12: {=_xlfn.STOCKHISTORY(I10,$B$2,$B$3,2,1,1)} -> Close | J12: Return | K12: {=_xlfn.STOCKHISTORY(K10,$B$2,$B$3,2,1,1)} -> Close | L12: Return | M12: {=_xlfn.STOCKHISTORY(M10,$B$2,$B$3,2,1,1)} -> Close | N12: Return | O12: {=_xlfn.STOCKHISTORY(O10,$B$2,$B$3,2,1,1)} -> Close | P12: Return | Q12: {=_xlfn.STOCKHISTORY(Q10,$B$2,$B$3,2,1,1)} -> Close | R12: Return | S12: {=_xlfn.STOCKHISTORY(S10,$B$2,$B$3,2,1,1)} -> Close | T12: Return | U12: {=_xlfn.STOCKHISTORY(U10,$B$2,$B$3,2,1,1)} -> Close | V12: Return | W12: {=_xlfn.STOCKHISTORY(W10,$B$2,$B$3,2,1,1)} -> Close | X12: Return
B13: 40544 | C13: 15.0236 | E13: 8.482 | G13: 17.7825 | I13: 85.2381 | K13: 53.3213 | M13: 23.651 | O13: 13.365 | Q13: 88.99 | S13: 0.598 | U13: 63.13 | W13: 41.05
B14: 40575 | C14: 15.3499 | D14: =(C14/C13)-1 -> 0.021719162 | E14: 8.6645 | F14: =(E14/E13)-1 -> 0.021516152 | G14: 18.05 | H14: =(G14/G13)-1 -> 0.015042879 | I14: 83.3293 | J14: =(I14/I13)-1 -> -0.022393742 | K14: 55.1301 | L14: =(K14/K13)-1 -> 0.033922654 | M14: 24.056 | N14: =(M14/M13)-1 -> 0.017124012 | O14: 13.8675 | P14: =(O14/O13)-1 -> 0.037598204 | Q14: 93.42 | R14: =(Q14/Q13)-1 -> 0.049780874 | S14: 0.5665 | T14: =(S14/S13)-1 -> -0.052675585 | U14: 63.05 | V14: =(U14/U13)-1 -> -0.0012672264 | W14: 42.58 | X14: =(W14/W13)-1 -> 0.03727162
B15: 40603 | C15: 14.6832 | D15: =(C15/C14)-1 -> -0.043433508 | E15: 9.0065 | F15: =(E15/E14)-1 -> 0.039471406 | G15: 17.925 | H15: =(G15/G14)-1 -> -0.0069252078 | I15: 87.8216 | J15: =(I15/I14)-1 -> 0.053910209 | K15: 56.8437 | L15: =(K15/K14)-1 -> 0.031082839 | M15: 25.172 | N15: =(M15/M14)-1 -> 0.046391753 | O15: 13.78 | P15: =(O15/O14)-1 -> -0.006309717 | Q15: 93.26 | R15: =(Q15/Q14)-1 -> -0.0017126954 | S15: 0.4615 | T15: =(S15/S14)-1 -> -0.18534863 | U15: 61.6 | V15: =(U15/U14)-1 -> -0.022997621 | W15: 45.2 | X15: =(W15/W14)-1 -> 0.061531235
B16: 40634 | C16: 13.6157 | D16: =(C16/C15)-1 -> -0.072702136 | E16: 9.7905 | F16: =(E16/E15)-1 -> 0.087048243 | G16: 18.655 | H16: =(G16/G15)-1 -> 0.040725244 | I16: 97.0376 | J16: =(I16/I15)-1 -> 0.10494001 | K16: 58.2907 | L16: =(K16/K15)-1 -> 0.025455767 | M16: 27.589 | N16: =(M16/M15)-1 -> 0.096019387 | O16: 14.1425 | P16: =(O16/O15)-1 -> 0.026306241 | Q16: 89.75 | R16: =(Q16/Q15)-1 -> -0.037636715 | S16: 0.5 | T16: =(S16/S15)-1 -> 0.083423619 | U16: 64.9 | V16: =(U16/U15)-1 -> 0.053571429 | W16: 49.23 | X16: =(W16/W15)-1 -> 0.089159292
B17: 40664 | C17: 13.2383 | D17: =(C17/C16)-1 -> -0.027718002 | E17: 9.8345 | F17: =(E17/E16)-1 -> 0.0044941525 | G17: 19.755 | H17: =(G17/G16)-1 -> 0.058965425 | I17: 97.751 | J17: =(I17/I16)-1 -> 0.0073517894 | K17: 56.6913 | L17: =(K17/K16)-1 -> -0.027438339 | M17: 28.705 | N17: =(M17/M16)-1 -> 0.040450904 | O17: 14.4875 | P17: =(O17/O16)-1 -> 0.024394555 | Q17: 85.72 | R17: =(Q17/Q16)-1 -> -0.044902507 | S17: 0.501 | T17: =(S17/S16)-1 -> 0.002 | U17: 67 | V17: =(U17/U16)-1 -> 0.032357473 | W17: 48.95 | X17: =(W17/W16)-1 -> -0.0056875889
B18: 40695 | C18: 12.6718 | D18: =(C18/C17)-1 -> -0.042792504 | E18: 10.2245 | F18: =(E18/E17)-1 -> 0.039656312 | G18: 19.23 | H18: =(G18/G17)-1 -> -0.02657555 | I18: 97.3846 | J18: =(I18/I17)-1 -> -0.0037482993 | K18: 56.7294 | L18: =(K18/K17)-1 -> 0.00067206079 | M18: 30.134 | N18: =(M18/M17)-1 -> 0.049782268 | O18: 14.365 | P18: =(O18/O17)-1 -> -0.0084555651 | Q18: 86.4 | R18: =(Q18/Q17)-1 -> 0.0079328045 | S18: 0.3984 | T18: =(S18/S17)-1 -> -0.20479042 | U18: 63.57 | V18: =(U18/U17)-1 -> -0.05119403 | W18: 51.58 | X18: =(W18/W17)-1 -> 0.053728294
B19: 40725 | C19: 15.1069 | D19: =(C19/C18)-1 -> 0.19216686 | E19: 11.126 | F19: =(E19/E18)-1 -> 0.088170571 | G19: 19.4 | H19: =(G19/G18)-1 -> 0.0088403536 | I19: 100.7105 | J19: =(I19/I18)-1 -> 0.034152217 | K19: 50.551 | L19: =(K19/K18)-1 -> -0.10891002 | M19: 30.325 | N19: =(M19/M18)-1 -> 0.0063383553 | O19: 13.8125 | P19: =(O19/O18)-1 -> -0.038461538 | Q19: 90.37 | R19: =(Q19/Q18)-1 -> 0.045949074 | S19: 0.3458 | T19: =(S19/S18)-1 -> -0.13202811 | U19: 61.49 | V19: =(U19/U18)-1 -> -0.032719836 | W19: 49.63 | X19: =(W19/W18)-1 -> -0.037805351
B20: 40756 | C20: 13.5371 | D20: =(C20/C19)-1 -> -0.10391278 | E20: 10.7615 | F20: =(E20/E19)-1 -> -0.0327611 | G20: 17.96 | H20: =(G20/G19)-1 -> -0.074226804 | I20: 90.6558 | J20: =(I20/I19)-1 -> -0.099837653 | K20: 45.5149 | L20: =(K20/K19)-1 -> -0.099624142 | M20: 32.971 | N20: =(M20/M19)-1 -> 0.08725474 | O20: 14.18 | P20: =(O20/O19)-1 -> 0.026606335 | Q20: 78.12 | R20: =(Q20/Q19)-1 -> -0.13555383 | S20: 0.3328 | T20: =(S20/S19)-1 -> -0.037593985 | U20: 63.68 | V20: =(U20/U19)-1 -> 0.035615547 | W20: 47.52 | X20: =(W20/W19)-1 -> -0.042514608
B21: 40787 | C21: 12.8885 | D21: =(C21/C20)-1 -> -0.047912773 | E21: 10.8115 | F21: =(E21/E20)-1 -> 0.0046461924 | G21: 15.51 | H21: =(G21/G20)-1 -> -0.13641425 | I21: 85.6333 | J21: =(I21/I20)-1 -> -0.055401861 | K21: 41.8021 | L21: =(K21/K20)-1 -> -0.081573287 | M21: 31.716 | N21: =(M21/M20)-1 -> -0.038063753 | O21: 13.505 | P21: =(O21/O20)-1 -> -0.047602257 | Q21: 59.73 | R21: =(Q21/Q20)-1 -> -0.23540707 | S21: 0.3128 | T21: =(S21/S20)-1 -> -0.060096154 | U21: 63.18 | V21: =(U21/U20)-1 -> -0.0078517588 | W21: 46.12 | X21: =(W21/W20)-1 -> -0.029461279
B22: 40817 | C22: 14.8304 | D22: =(C22/C21)-1 -> 0.1506692 | E22: 10.6755 | F22: =(E22/E21)-1 -> -0.012579198 | G22: 17.285 | H22: =(G22/G21)-1 -> 0.1144423 | I22: 92.5549 | J22: =(I22/I21)-1 -> 0.080828369 | K22: 49.8846 | L22: =(K22/K21)-1 -> 0.19335153 | M22: 34.724 | N22: =(M22/M21)-1 -> 0.09484172 | O22: 14.1 | P22: =(O22/O21)-1 -> 0.044057756 | Q22: 73.47 | R22: =(Q22/Q21)-1 -> 0.23003516 | S22: 0.37 | T22: =(S22/S21)-1 -> 0.18286445 | U22: 63.99 | V22: =(U22/U21)-1 -> 0.012820513 | W22: 47.99 | X22: =(W22/W21)-1 -> 0.040546401
B23: 40848 | C23: 14.9993 | D23: =(C23/C22)-1 -> 0.011388769 | E23: 9.6145 | F23: =(E23/E22)-1 -> -0.099386446 | G23: 17.555 | H23: =(G23/G22)-1 -> 0.01562048 | I23: 96.4206 | J23: =(I23/I22)-1 -> 0.041766562 | K23: 51.5506 | L23: =(K23/K22)-1 -> 0.03339708 | M23: 37.455 | N23: =(M23/M22)-1 -> 0.078648773 | O23: 13.86 | P23: =(O23/O22)-1 -> -0.017021277 | Q23: 75.33 | R23: =(Q23/Q22)-1 -> 0.025316456 | S23: 0.3908 | T23: =(S23/S22)-1 -> 0.056216216 | U23: 64.57 | V23: =(U23/U22)-1 -> 0.0090639162 | W23: 48.77 | X23: =(W23/W22)-1 -> 0.016253386
B24: 40878 | C24: 16.1632 | D24: =(C24/C23)-1 -> 0.077596955 | E24: 8.655 | F24: =(E24/E23)-1 -> -0.099797181 | G24: 17.855 | H24: =(G24/G23)-1 -> 0.017089148 | I24: 97.751 | J24: =(I24/I23)-1 -> 0.013797881 | K24: 51.741 | L24: =(K24/K23)-1 -> 0.0036934585 | M24: 37.282 | N24: =(M24/M23)-1 -> -0.004618876 | O24: 15.22 | P24: =(O24/O23)-1 -> 0.098124098 | Q24: 68.31 | R24: =(Q24/Q23)-1 -> -0.093189964 | S24: 0.3465 | T24: =(S24/S23)-1 -> -0.11335722 | U24: 66.71 | V24: =(U24/U23)-1 -> 0.033142326 | W24: 50.68 | X24: =(W24/W23)-1 -> 0.03916342
B25: 40909 | C25: 14.5168 | D25: =(C25/C24)-1 -> -0.10186102 | E25: 9.722 | F25: =(E25/E24)-1 -> 0.12328134 | G25: 19.63 | H25: =(G25/G24)-1 -> 0.099411929 | I25: 115.643 | J25: =(I25/I24)-1 -> 0.18303649 | K25: 55.2538 | L25: =(K25/K24)-1 -> 0.067892001 | M25: 35.557 | N25: =(M25/M24)-1 -> -0.046268977 | O25: 14.9625 | P25: =(O25/O24)-1 -> -0.016918528 | Q25: 75.17 | R25: =(Q25/Q24)-1 -> 0.10042454 | S25: 0.3693 | T25: =(S25/S24)-1 -> 0.065800866 | U25: 63.04 | V25: =(U25/U24)-1 -> -0.055014241 | W25: 51.79 | X25: =(W25/W24)-1 -> 0.021902131
... B84: 42705 | C84: 39.6225 | D84: =(C84/C83)-1 -> 0.021356395 | E84: 37.4935 | F84: =(E84/E83)-1 -> -0.00093262454 | G84: 37.535 | H84: =(G84/G83)-1 -> 0.00013322675 | I84: 357.41 | J84: =(I84/I83)-1 -> 0.055053725 | K84: 110.9201 | L84: =(K84/K83)-1 -> 0.01676394 | M84: 103.25 | N84: =(M84/M83)-1 -> 0.010273973 | O84: 29.865 | P84: =(O84/O83)-1 -> 0.04578482 | Q84: 83.95 | R84: =(Q84/Q83)-1 -> -0.001189768 | S84: 2.6685 | T84: =(S84/S83)-1 -> 0.15770065 | U84: 84.08 | V84: =(U84/U83)-1 -> 0.019645889 | W84: 160.04 | X84: =(W84/W83)-1 -> 0.010864073
D85: =AVERAGE(D37:D73) -> 0.022557358 | E85: MEAN | F85: =AVERAGE(F37:F73) -> 0.026775811 | G85: MEAN | H85: =AVERAGE(H37:H73) -> 0.012130714 | I85: MEAN | J85: =AVERAGE(J37:J73) -> 0.013507878 | K85: MEAN | L85: =AVERAGE(L37:L73) -> 0.013825202 | M85: MEAN | N85: =AVERAGE(N37:N73) -> 0.01756453 | O85: MEAN | P85: =AVERAGE(P37:P73) -> 0.014204404 | Q85: MEAN | R85: =AVERAGE(R37:R73) -> 0.0035004661 | S85: MEAN | T85: =AVERAGE(T37:T73) -> 0.026011421 | U85: MEAN | V85: =AVERAGE(V37:V73) -> 0.0058345301 | W85: MEAN | X85: =AVERAGE(X37:X73) -> 0.021670714
D86: =_xlfn.STDEV.P(D37:D73) -> 0.059471886 | E86: SD | F86: =_xlfn.STDEV.P(F37:F73) -> 0.085965471 | G86: SD | H86: =_xlfn.STDEV.P(H37:H73) -> 0.050118455 | I86: SD | J86: =_xlfn.STDEV.P(J37:J73) -> 0.052550215 | K86: SD | L86: =_xlfn.STDEV.P(L37:L73) -> 0.034926689 | M86: SD | N86: =_xlfn.STDEV.P(N37:N73) -> 0.052716235 | O86: SD | P86: =_xlfn.STDEV.P(P37:P73) -> 0.048379163 | Q86: SD | R86: =_xlfn.STDEV.P(R37:R73) -> 0.069400643 | S86: SD | T86: =_xlfn.STDEV.P(T37:T73) -> 0.06730039 | U86: SD | V86: =_xlfn.STDEV.P(V37:V73) -> 0.040681677 | W86: SD | X86: =_xlfn.STDEV.P(X37:X73) -> 0.047505347
E87: Annual | G87: Annual | I87: Annual | K87: Annual | M87: Annual | O87: Annual | Q87: Annual | S87: Annual | U87: Annual | W87: Annual
