Workbook

Sheet Sheet1 (2)
A1: Dates
A2: Start Date | B2: 42736
A3: End | B3: 44926
A4: Interval | B4: 1
C8: 1 | D8: 2 | E8: 3 | F8: 4 | G8: 5 | H8: 6 | I8: 7 | J8: 8 | K8: 9 | L8: 10 | M8: 11
B9: Company | C9: #VALUE! | D9: #VALUE! | E9: BALL CORPORATION (XNYS:BALL) | F9: #VALUE! | G9: #VALUE! | H9: #VALUE! | I9: #VALUE! | J9: #VALUE! | K9: #VALUE! | L9: #VALUE! | M9: #VALUE! | N9: #VALUE!
B10: Ticker | C10: GOOGL | D10: AMZN | E10: BALL | F10: EQIX | G10: HON | H10: MA | I10: NEE | J10: SLB | K10: NVDA | L10: PG | M10: UNH
B11: {=_xlfn.STOCKHISTORY(C10,B2,B3,0,1,0,1)} -> Date | C11: Close | D11: {=_xlfn.STOCKHISTORY(D10,$B$2,$B$3,0,1,1)} -> Close | E11: {=_xlfn.STOCKHISTORY(E10,$B$2,$B$3,0,1,1)} -> Close | F11: {=_xlfn.STOCKHISTORY(F10,$B$2,$B$3,0,1,1)} -> Close | G11: {=_xlfn.STOCKHISTORY(G10,$B$2,$B$3,0,1,1)} -> Close | H11: {=_xlfn.STOCKHISTORY(H10,$B$2,$B$3,0,1,1)} -> Close | I11: {=_xlfn.STOCKHISTORY(I10,$B$2,$B$3,0,1,1)} -> Close | J11: {=_xlfn.STOCKHISTORY(J10,$B$2,$B$3,0,1,1)} -> Close | K11: {=_xlfn.STOCKHISTORY(K10,$B$2,$B$3,0,1,1)} -> Close | ... M11: {=_xlfn.STOCKHISTORY(M10,$B$2,$B$3,0,1,1)} -> Close | N11: {=_xlfn.STOCKHISTORY(N9,$B$2,$B$3,0,1,1)} -> Close
B12: 42738 | C12: 40.4005 | D12: 37.6835 | E12: 37.875 | F12: 358.72 | G12: 111.236 | H12: 105.39 | I12: 29.68 | J12: 84.8 | K12: 2.5503 | L12: 84.2 | M12: 161.45 | N12: 2257.83
B13: 42739 | C13: 40.3885 | D13: 37.859 | E13: 38.45 | F13: 365.91 | G13: 111.5424 | H13: 106.39 | I13: 29.7675 | J13: 85.43 | K13: 2.6098 | L13: 84.5 | M13: 161.91 | N13: 2270.75
B14: 42740 | C14: 40.651 | D14: 39.0225 | E14: 38.43 | F14: 369.75 | G14: 111.7913 | H14: 106.99 | I14: 29.75 | J14: 85.3 | K14: 2.5435 | L14: 85.06 | M14: 162.18 | N14: 2269
B15: 42741 | C15: 41.2605 | D15: 39.7995 | E15: 38.6 | F15: 370.49 | G15: 113.486 | H15: 107.76 | I15: 29.6625 | J15: 86.48 | K15: 2.5775 | L15: 85.03 | M15: 162.41 | N15: 2276.98
B16: 42744 | C16: 41.359 | D16: 39.846 | E16: 37.99 | F16: 373.19 | G16: 112.5477 | H16: 107.55 | I16: 29.5875 | J16: 85.77 | K16: 2.682 | L16: 84.4 | M16: 161.95 | N16: 2268.9
B17: 42745 | C17: 41.3005 | D17: 39.795 | E17: 37.81 | F17: 370.03 | G17: 112.8349 | H17: 107.32 | I17: 29.645 | J17: 84.6 | K17: 2.6618 | L17: 83.49 | M17: 161.58 | N17: 2268.9
B18: 42746 | C18: 41.493 | D18: 39.951 | E18: 38.355 | F18: 371.58 | G18: 112.9881 | H18: 107.81 | I18: 29.8525 | J18: 85.66 | K18: 2.629 | L18: 83.75 | M18: 161.89 | N18: 2275.32
B19: 42747 | C19: 41.4765 | D19: 40.682 | E19: 38.525 | F19: 374.15 | G19: 112.6243 | H19: 108.71 | I19: 29.875 | J19: 85.33 | K19: 2.586 | L19: 83.84 | M19: 162.36 | N19: 2270.44
B20: 42748 | C20: 41.547 | D20: 40.857 | E20: 38.085 | F20: 374.95 | G20: 113.0456 | H20: 108.7 | I20: 29.7625 | J20: 84.82 | K20: 2.5858 | L20: 84.01 | M20: 161.8 | N20: 2274.64
B21: 42752 | C21: 41.373 | D21: 40.486 | E21: 38.245 | F21: 376.13 | G21: 112.2413 | H21: 108.4 | I21: 30.055 | J21: 86.43 | K21: 2.5278 | L21: 85.21 | M21: 160.66 | N21: 2267.89
B22: 42753 | C22: 41.451 | D22: 40.374 | E22: 38.49 | F22: 376.73 | G22: 113.036 | H22: 108.66 | I22: 30.0075 | J22: 87.48 | K22: 2.5738 | L22: 84.93 | M22: 157.74 | N22: 2271.89
B23: 42754 | C23: 41.2185 | D23: 40.452 | E23: 37.805 | F23: 381.15 | G23: 112.8924 | H23: 108.53 | I23: 29.82 | J23: 87.2 | K23: 2.629 | L23: 84.7 | M23: 158.7 | N23: 2263.69
... B1517: 44918 | C1517: 89.23 | D1517: 85.25 | E1517: 51.63 | F1517: 654.58 | G1517: 213.87 | H1517: 343.6 | I1517: 84.17 | J1517: 52.99 | K1517: 15.206 | L1517: 152.62 | M1517: 531.31 | N1517: 3839.5
B1518: 44922 | C1518: 87.39 | D1518: 83.04 | E1518: 51.79 | F1518: 652.54 | G1518: 214.89 | H1518: 346.16 | I1518: 84 | J1518: 53.5 | K1518: 14.121 | L1518: 153.95 | M1518: 531.99
B1519: 44923 | C1519: 86.02 | D1519: 81.82 | E1519: 50.58 | F1519: 665.37 | G1519: 212.19 | H1519: 341.95 | I1519: 83.16 | J1519: 52.6 | K1519: 14.036 | L1519: 151.96 | M1519: 528.45
B1520: 44924 | C1520: 88.45 | D1520: 84.18 | E1520: 51.62 | F1520: 655.03 | G1520: 214.75 | H1520: 348.21 | I1520: 84.08 | J1520: 52.91 | K1520: 14.603 | L1520: 152.59 | M1520: 529.88
B1521: 44925 | C1521: 88.23 | D1521: 84 | E1521: 51.14 | G1521: 214.3 | H1521: 347.73 | I1521: 83.6 | J1521: 53.46 | K1521: 14.614 | L1521: 151.56 | M1521: 530.18

Sheet Sheet1
A1: Dates
A2: Start Date | B2: 42005
A3: End | B3: 44926
A4: Interval | B4: 1
C8: 1 | E8: 2 | G8: 3 | I8: 4 | K8: 5 | M8: 6 | O8: 7 | Q8: 8 | S8: 9 | U8: 10 | W8: 11
B9: Company | C9: #VALUE! | D9: Return | E9: #VALUE! | G9: BALL CORPORATION (XNYS:BALL) | I9: #VALUE! | K9: #VALUE! | M9: #VALUE! | O9: #VALUE! | Q9: #VALUE! | S9: #VALUE! | U9: #VALUE! | W9: #VALUE! | Y9: #VALUE! | AA9: #VALUE! | AD9: #VALUE!
B10: Ticker | C10: GOOGL | E10: AMZN | G10: BALL | I10: EQIX | K10: HON | M10: MA | O10: NEE | Q10: SLB | S10: NVDA | U10: PG | W10: UNH
B11: {=_xlfn.STOCKHISTORY(C10,B2,B3,2,1,0,1)} -> Date | C11: Close | E11: {=_xlfn.STOCKHISTORY(E10,$B$2,$B$3,2,1,1)} -> Close | G11: {=_xlfn.STOCKHISTORY(G10,$B$2,$B$3,2,1,1)} -> Close | I11: {=_xlfn.STOCKHISTORY(I10,$B$2,$B$3,2,1,1)} -> Close | K11: {=_xlfn.STOCKHISTORY(K10,$B$2,$B$3,2,1,1)} -> Close | M11: {=_xlfn.STOCKHISTORY(M10,$B$2,$B$3,2,1,1)} -> Close | O11: {=_xlfn.STOCKHISTORY(O10,$B$2,$B$3,2,1,1)} -> Close | Q11: {=_xlfn.STOCKHISTORY(Q10,$B$2,$B$3,2,1,1)} -> Close | S11: {=_xlfn.STOCKHISTORY(S10,$B$2,$B$3,2,1,1)} -> Close | U11: {=_xlfn.STOCKHISTORY(U10,$B$2,$B$3,2,1,1)} -> Close | W11: {=_xlfn.STOCKHISTORY(W10,$B$2,$B$3,2,1,1)} -> Close | Y11: {=_xlfn.STOCKHISTORY(Y9,$B$2,$B$3,2,1,1)} -> Close | AA11: {=_xlfn.STOCKHISTORY(AA9,$B$2,$B$3,2,1,1)} -> Close | AD11: {=_xlfn.STOCKHISTORY(AD9,$B$2,$B$3,2,1,1)} -> Close
B12: 42005 | C12: 26.8775 | E12: 17.7265 | G12: 31.665 | I12: 210.647 | K12: 93.0671 | M12: 82.03 | O12: 27.31 | Q12: 82.39 | S12: 0.4801 | U12: 84.29 | W12: 106.25 | Y12: 1994.99 | AA12: 16.75 | AB12: 16.75 | AD12: 101.1
B13: 42036 | C13: 28.1315 | E13: 19.008 | G13: 35.855 | I13: 217.7524 | K13: 97.8461 | M13: 90.13 | O13: 25.865 | Q13: 84.16 | S13: 0.5515 | U13: 85.13 | W13: 113.63 | Y13: 2104.5 | AA13: 20.02 | AB13: 20.02 | AD13: 108.4
B14: 42064 | C14: 27.735 | E14: 18.605 | G14: 35.32 | I14: 226.1788 | K14: 99.3027 | M14: 86.39 | O14: 26.0125 | Q14: 83.44 | S14: 0.5231 | U14: 81.94 | W14: 118.29 | Y14: 2067.89 | AA14: 19.34 | AB14: 19.34 | AD14: 105.6
B15: 42095 | C15: 27.4385 | E15: 21.089 | G15: 36.705 | I15: 248.5976 | K15: 96.0754 | M15: 90.21 | O15: 25.2325 | Q15: 94.61 | S15: 0.5549 | U15: 79.51 | W15: 111.4 | Y15: 2085.51 | AA15: 20.46 | AB15: 20.46 | AD15: 107.63
B16: 42125 | C16: 27.266 | E16: 21.4615 | G16: 35.495 | I16: 260.3898 | K16: 99.1979 | M16: 92.26 | O16: 25.585 | Q16: 90.77 | S16: 0.5533 | U16: 78.39 | W16: 120.21 | Y16: 2107.39 | AA16: 20.95 | AB16: 20.95 | AD16: 110.05
B17: 42156 | C17: 27.002 | E17: 21.7045 | G17: 35.075 | I17: 246.7229 | K17: 97.075 | M17: 93.48 | O17: 24.5075 | Q17: 86.19 | S17: 0.5028 | U17: 78.24 | W17: 122 | Y17: 2063.11 | AA17: 23.35 | AB17: 23.35 | AD17: 107.07
B18: 42186 | C18: 32.875 | E18: 26.8075 | G18: 33.92 | I18: 270.9192 | K18: 100.0071 | M18: 97.4 | O18: 26.3 | Q18: 82.82 | S18: 0.4988 | U18: 76.7 | W18: 121.4 | Y18: 2103.84 | AA18: 22.05 | AB18: 22.05 | AD18: 111.95
B19: 42217 | C19: 32.391 | E19: 25.6445 | G19: 32.955 | I19: 262.0411 | K19: 94.5046 | M19: 92.37 | O19: 24.6025 | Q19: 77.37 | S19: 0.562 | U19: 70.67 | W19: 115.7 | Y19: 1972.18 | AA19: 22 | AB19: 22 | AD19: 104.31
B20: 42248 | C20: 31.9185 | E20: 25.5945 | G20: 31.1 | I20: 265.5671 | K20: 90.1445 | M20: 90.12 | O20: 24.3875 | Q20: 68.97 | S20: 0.6163 | U20: 71.94 | W20: 116.01 | Y20: 1920.03 | AA20: 20.6 | AB20: 20.6 | AD20: 101.76
B21: 42278 | C21: 36.8695 | E21: 31.295 | G21: 34.25 | I21: 296.68 | K21: 98.3221 | M21: 98.99 | O21: 25.665 | Q21: 78.16 | S21: 0.7093 | U21: 76.38 | W21: 117.78 | Y21: 2079.36 | AA21: 21.51 | AB21: 21.51 | AD21: 113.33
B22: 42309 | C22: 38.1425 | E22: 33.24 | G22: 34.71 | I22: 296.5 | K22: 98.9599 | M22: 97.92 | O22: 24.965 | Q22: 77.15 | S22: 0.793 | U22: 74.84 | W22: 112.71 | Y22: 2080.41 | AA22: 22.18 | AB22: 22.18 | AD22: 114.02
B23: 42339 | C23: 38.9005 | E23: 33.7945 | G23: 36.365 | I23: 302.4 | K23: 98.5982 | M23: 97.36 | O23: 25.9725 | Q23: 69.75 | S23: 0.824 | U23: 79.41 | W23: 117.64 | Y23: 2043.94 | AA23: 22.69 | AB23: 22.69 | AD23: 111.86
... B35: 42705 | C35: 39.6225 | E35: 37.4935 | G35: 37.535 | I35: 357.41 | K35: 110.9201 | M35: 103.25 | O35: 29.865 | Q35: 83.95 | S35: 2.6685 | U35: 84.08 | W35: 160.04 | Y35: 2238.83 | AA35: 24.46 | AB35: 24.46 | AD35: 118.48
B36: 42736 | C36: 41.0095 | D36: =(C36/C35)-1 -> 0.035005363 | E36: 41.174 | F36: =(E36/E35)-1 -> 0.098163682 | G36: 38.13 | H36: =(G36/G35)-1 -> 0.015851872 | I36: 384.98 | J36: =(I36/I35)-1 -> 0.077138301 | K36: 113.2849 | L36: =(K36/K35)-1 -> 0.021319851 | M36: 106.33 | N36: =(M36/M35)-1 -> 0.029830508 | O36: 30.93 | P36: =(O36/O35)-1 -> 0.035660472 | Q36: 83.71 | R36: =(Q36/Q35)-1 -> -0.0028588446 | S36: 2.7295 | T36: =(S36/S35)-1 -> 0.022859284 | U36: 87.6 | V36: =(U36/U35)-1 -> 0.041864891 | W36: 162.1 | X36: =(W36/W35)-1 -> 0.012871782 | Y36: 2278.87 | Z36: =(Y36/Y35)-1 -> 0.017884341 | AA36: 24.51 | AB36: 24.51 | AC36: =AB36/10 -> 2.451 | AD36: 124.57 | AE36: =(AD36/AD35)-1 -> 0.05140108
B37: 42767 | C37: 42.2465 | D37: =(C37/C36)-1 -> 0.030163743 | E37: 42.252 | F37: =(E37/E36)-1 -> 0.026181571 | G37: 36.765 | H37: =(G37/G36)-1 -> -0.035798584 | I37: 376.07 | J37: =(I37/I36)-1 -> -0.023144059 | K37: 119.202 | L37: =(K37/K36)-1 -> 0.052232027 | M37: 110.46 | N37: =(M37/M36)-1 -> 0.038841343 | O37: 32.75 | P37: =(O37/O36)-1 -> 0.058842548 | Q37: 80.36 | R37: =(Q37/Q36)-1 -> -0.040019114 | S37: 2.537 | T37: =(S37/S36)-1 -> -0.070525737 | U37: 91.07 | V37: =(U37/U36)-1 -> 0.039611872 | W37: 165.38 | X37: =(W37/W36)-1 -> 0.020234423 | Y37: 2363.64 | Z37: =(Y37/Y36)-1 -> 0.037198261 | AA37: 23.58 | AB37: 23.58 | AC37: =AB37/10 -> 2.358 | AD37: 130.02 | AE37: =(AD37/AD36)-1 -> 0.043750502
B38: 42795 | C38: 42.39 | D38: =(C38/C37)-1 -> 0.0033967311 | E38: 44.327 | F38: =(E38/E37)-1 -> 0.049110101 | G38: 37.13 | H38: =(G38/G37)-1 -> 0.0099279206 | I38: 400.37 | J38: =(I38/I37)-1 -> 0.06461563 | K38: 119.5562 | L38: =(K38/K37)-1 -> 0.0029714267 | M38: 112.47 | N38: =(M38/M37)-1 -> 0.018196632 | O38: 32.0925 | P38: =(O38/O37)-1 -> -0.020076336 | Q38: 78.1 | R38: =(Q38/Q37)-1 -> -0.028123444 | S38: 2.7233 | T38: =(S38/S37)-1 -> 0.073433189 | U38: 89.85 | V38: =(U38/U37)-1 -> -0.013396289 | W38: 164.01 | X38: =(W38/W37)-1 -> -0.0082839521 | Y38: 2362.72 | Z38: =(Y38/Y37)-1 -> -0.00038923017 | AA38: 23.96 | AB38: 23.96 | AC38: =AB38/10 -> 2.396 | AD38: 132.38 | AE38: =(AD38/AD37)-1 -> 0.018151054
B39: 42826 | C39: 46.226 | D39: =(C39/C38)-1 -> 0.090493041 | E39: 46.2495 | F39: =(E39/E38)-1 -> 0.043370857 | G39: 38.445 | H39: =(G39/G38)-1 -> 0.035416106 | I39: 417.7 | J39: =(I39/I38)-1 -> 0.043284961 | K39: 125.5594 | L39: =(K39/K38)-1 -> 0.050212369 | M39: 116.32 | N39: =(M39/M38)-1 -> 0.034231351 | O39: 33.39 | P39: =(O39/O38)-1 -> 0.040430007 | Q39: 72.59 | R39: =(Q39/Q38)-1 -> -0.070550576 | S39: 2.6075 | T39: =(S39/S38)-1 -> -0.04252194 | U39: 87.33 | V39: =(U39/U38)-1 -> -0.028046745 | W39: 174.88 | X39: =(W39/W38)-1 -> 0.066276447 | Y39: 2384.2 | Z39: =(Y39/Y38)-1 -> 0.0090912169 | AA39: 22.82 | AB39: 22.82 | AC39: =AB39/10 -> 2.282 | AD39: 135.99 | AE39: =(AD39/AD38)-1 -> 0.02726998
B40: 42856 | C40: 49.3545 | D40: =(C40/C39)-1 -> 0.067678363 | E40: 49.731 | F40: =(E40/E39)-1 -> 0.075276489 | G40: 40.9 | H40: =(G40/G39)-1 -> 0.063857459 | I40: 441.01 | J40: =(I40/I39)-1 -> 0.055805602 | K40: 127.3307 | L40: =(K40/K39)-1 -> 0.014107267 | M40: 122.88 | N40: =(M40/M39)-1 -> 0.056396149 | O40: 35.36 | P40: =(O40/O39)-1 -> 0.058999701 | Q40: 69.59 | R40: =(Q40/Q39)-1 -> -0.041328007 | S40: 3.6088 | T40: =(S40/S39)-1 -> 0.38400767 | U40: 88.09 | V40: =(U40/U39)-1 -> 0.0087026222 | W40: 175.18 | X40: =(W40/W39)-1 -> 0.001715462 | Y40: 2411.8 | Z40: =(Y40/Y39)-1 -> 0.01157621 | AA40: 21.96 | AB40: 21.96 | AC40: =AB40/10 -> 2.196 | AD40: 141.29 | AE40: =(AD40/AD39)-1 -> 0.038973454
B41: 42887 | C41: 46.484 | D41: =(C41/C40)-1 -> -0.058160857 | E41: 48.4 | F41: =(E41/E40)-1 -> -0.02676399 | G41: 42.21 | H41: =(G41/G40)-1 -> 0.03202934 | I41: 429.16 | J41: =(I41/I40)-1 -> -0.026870139 | K41: 127.6179 | L41: =(K41/K40)-1 -> 0.002255544 | M41: 121.45 | N41: =(M41/M40)-1 -> -0.01163737 | O41: 35.0325 | P41: =(O41/O40)-1 -> -0.0092618778 | Q41: 65.84 | R41: =(Q41/Q40)-1 -> -0.053887053 | S41: 3.614 | T41: =(S41/S40)-1 -> 0.0014409222 | U41: 87.15 | V41: =(U41/U40)-1 -> -0.010670905 | W41: 185.42 | X41: =(W41/W40)-1 -> 0.058454161 | Y41: 2423.41 | Z41: =(Y41/Y40)-1 -> 0.004813832 | AA41: 23.02 | AB41: 23.02 | AC41: =AB41/10 -> 2.302 | AD41: 137.64 | AE41: =(AD41/AD40)-1 -> -0.025833392
B42: 42917 | C42: 47.275 | D42: =(C42/C41)-1 -> 0.017016608 | E42: 49.389 | F42: =(E42/E41)-1 -> 0.020433884 | G42: 41.9 | H42: =(G42/G41)-1 -> -0.0073442312 | I42: 450.73 | J42: =(I42/I41)-1 -> 0.050260975 | K42: 130.3275 | L42: =(K42/K41)-1 -> 0.021232131 | M42: 127.8 | N42: =(M42/M41)-1 -> 0.052284891 | O42: 36.5225 | P42: =(O42/O41)-1 -> 0.042531935 | Q42: 68.6 | R42: =(Q42/Q41)-1 -> 0.041919806 | S42: 4.0628 | T42: =(S42/S41)-1 -> 0.12418373 | U42: 90.82 | V42: =(U42/U41)-1 -> 0.042111302 | W42: 191.81 | X42: =(W42/W41)-1 -> 0.034462302 | Y42: 2470.3 | Z42: =(Y42/Y41)-1 -> 0.019348769 | AA42: 22.92 | AB42: 22.92 | AC42: =AB42/10 -> 2.292 | AD42: 143.23 | AE42: =(AD42/AD41)-1 -> 0.040613194
B43: 42948 | C43: 47.762 | D43: =(C43/C42)-1 -> 0.010301428 | E43: 49.03 | F43: =(E43/E42)-1 -> -0.007268825 | G43: 39.99 | H43: =(G43/G42)-1 -> -0.045584726 | I43: 468.41 | J43: =(I43/I42)-1 -> 0.039225257 | K43: 132.386 | L43: =(K43/K42)-1 -> 0.015794825 | M43: 133.3 | N43: =(M43/M42)-1 -> 0.043035994 | O43: 37.6275 | P43: =(O43/O42)-1 -> 0.030255322 | Q43: 63.51 | R43: =(Q43/Q42)-1 -> -0.074198251 | S43: 4.236 | T43: =(S43/S42)-1 -> 0.042630698 | U43: 92.27 | V43: =(U43/U42)-1 -> 0.015965646 | W43: 198.9 | X43: =(W43/W42)-1 -> 0.036963662 | Y43: 2471.65 | Z43: =(Y43/Y42)-1 -> 0.00054649233 | AA43: 21.21 | AB43: 21.21 | AC43: =AB43/10 -> 2.121 | AD43: 146.2 | AE43: =(AD43/AD42)-1 -> 0.020735879
B44: 42979 | C44: 48.686 | D44: =(C44/C43)-1 -> 0.019345924 | E44: 48.0675 | F44: =(E44/E43)-1 -> -0.019630838 | G44: 41.3 | H44: =(G44/G43)-1 -> 0.03275819 | I44: 446.3 | J44: =(I44/I43)-1 -> -0.047202237 | K44: 135.7083 | L44: =(K44/K43)-1 -> 0.025095554 | M44: 141.2 | N44: =(M44/M43)-1 -> 0.059264816 | O44: 36.6375 | P44: =(O44/O43)-1 -> -0.026310544 | Q44: 69.76 | R44: =(Q44/Q43)-1 -> 0.098409699 | S44: 4.4693 | T44: =(S44/S43)-1 -> 0.055075543 | U44: 90.98 | V44: =(U44/U43)-1 -> -0.013980709 | W44: 195.85 | X44: =(W44/W43)-1 -> -0.015334339 | Y44: 2519.36 | Z44: =(Y44/Y43)-1 -> 0.019302895 | AA44: 23.26 | AB44: 23.26 | AC44: =AB44/10 -> 2.326 | AD44: 145.45 | AE44: =(AD44/AD43)-1 -> -0.005129959
B45: 43009 | C45: 51.652 | D45: =(C45/C44)-1 -> 0.060921004 | E45: 55.264 | F45: =(E45/E44)-1 -> 0.14971654 | G45: 42.93 | H45: =(G45/G44)-1 -> 0.039467312 | I45: 463.5 | J45: =(I45/I44)-1 -> 0.038539099 | K45: 138.0253 | L45: =(K45/K44)-1 -> 0.017073385 | M45: 148.77 | N45: =(M45/M44)-1 -> 0.053611898 | O45: 38.7675 | P45: =(O45/O44)-1 -> 0.058137155 | Q45: 64 | R45: =(Q45/Q44)-1 -> -0.082568807 | S45: 5.1703 | T45: =(S45/S44)-1 -> 0.15684783 | U45: 86.34 | V45: =(U45/U44)-1 -> -0.05100022 | W45: 210.22 | X45: =(W45/W44)-1 -> 0.073372479 | Y45: 2575.26 | Z45: =(Y45/Y44)-1 -> 0.022188175 | AA45: 23.76 | AB45: 23.76 | AC45: =AB45/10 -> 2.376 | AD45: 152.15 | AE45: =(AD45/AD44)-1 -> 0.046063939
B46: 43040 | C46: 51.8085 | D46: =(C46/C45)-1 -> 0.0030298924 | E46: 58.8375 | F46: =(E46/E45)-1 -> 0.064662348 | G46: 39.91 | H46: =(G46/G45)-1 -> -0.070347077 | I46: 464.49 | J46: =(I46/I45)-1 -> 0.0021359223 | K46: 149.3232 | L46: =(K46/K45)-1 -> 0.081853834 | M46: 150.47 | N46: =(M46/M45)-1 -> 0.011427035 | O46: 39.51 | P46: =(O46/O45)-1 -> 0.019152641 | Q46: 62.85 | R46: =(Q46/Q45)-1 -> -0.01796875 | S46: 5.0178 | T46: =(S46/S45)-1 -> -0.029495387 | U46: 89.99 | V46: =(U46/U45)-1 -> 0.042274728 | W46: 228.17 | X46: =(W46/W45)-1 -> 0.085386738 | Y46: 2647.58 | Z46: =(Y46/Y45)-1 -> 0.028082601 | AA46: 24.17 | AB46: 24.17 | AC46: =AB46/10 -> 2.417 | AD46: 155.15 | AE46: =(AD46/AD45)-1 -> 0.019717384
B47: 43070 | C47: 52.67 | D47: =(C47/C46)-1 -> 0.016628546 | E47: 58.4735 | F47: =(E47/E46)-1 -> -0.0061865307 | G47: 37.85 | H47: =(G47/G46)-1 -> -0.051616136 | I47: 453.22 | J47: =(I47/I46)-1 -> -0.02426317 | K47: 146.8338 | L47: =(K47/K46)-1 -> -0.016671221 | M47: 151.36 | N47: =(M47/M46)-1 -> 0.0059148003 | O47: 39.0475 | P47: =(O47/O46)-1 -> -0.011705897 | Q47: 67.39 | R47: =(Q47/Q46)-1 -> 0.072235481 | S47: 4.8375 | T47: =(S47/S46)-1 -> -0.035932082 | U47: 91.88 | V47: =(U47/U46)-1 -> 0.021002334 | W47: 220.46 | X47: =(W47/W46)-1 -> -0.033790595 | Y47: 2673.61 | Z47: =(Y47/Y46)-1 -> 0.0098316198 | AA47: 24.05 | AB47: 24.05 | AC47: =AB47/10 -> 2.405 | AD47: 155.76 | AE47: =(AD47/AD46)-1 -> 0.003931679
... B107: 44896 | C107: 88.23 | D107: =(C107/C106)-1 -> -0.12634914 | E107: 84 | F107: =(E107/E106)-1 -> -0.12989434 | G107: 51.14 | H107: =(G107/G106)-1 -> -0.088088445 | I107: 655.03 | J107: =(I107/I106)-1 -> -0.051574604 | K107: 214.3 | L107: =(K107/K106)-1 -> -0.023912548 | M107: 347.73 | N107: =(M107/M106)-1 -> -0.024326599 | O107: 83.6 | P107: =(O107/O106)-1 -> -0.012987013 | Q107: 53.46 | R107: =(Q107/Q106)-1 -> 0.037051406 | S107: 14.614 | T107: =(S107/S106)-1 -> -0.13644153 | U107: 151.56 | V107: =(U107/U106)-1 -> 0.016090105 | W107: 530.18 | X107: =(W107/W106)-1 -> -0.032094348 | Y107: 3839.5 | Z107: =(Y107/Y106)-1 -> -0.058971449 | AA107: 38.79 | AB107: 38.79 | AC107: =AB107/10 -> 3.879 | AD107: 266.28 | AE107: =(AD107/AD106)-1 -> -0.09230979

Sheet ReturnsVtime
A1: Ticker | B1: GOOGL | C1: AMZN | D1: BALL | E1: EQIX | F1: HON | G1: MA | H1: NEE | I1: SLB | J1: NVDA | K1: PG | L1: UNH | M1: S&P 500 | N1: NASDAQ
A2: 42736 | B2: 0.035005363 | C2: 0.098163682 | D2: 0.015851872 | E2: 0.077138301 | F2: 0.021319851 | G2: 0.029830508 | H2: 0.035660472 | I2: -0.0028588446 | J2: 0.022859284 | K2: 0.041864891 | L2: 0.012871782 | M2: 0.017884341 | N2: 0.05140108
A3: 42767 | B3: 0.030163743 | C3: 0.026181571 | D3: -0.035798584 | E3: -0.023144059 | F3: 0.052232027 | G3: 0.038841343 | H3: 0.058842548 | I3: -0.040019114 | J3: -0.070525737 | K3: 0.039611872 | L3: 0.020234423 | M3: 0.037198261 | N3: 0.043750502
A4: 42795 | B4: 0.0033967311 | C4: 0.049110101 | D4: 0.0099279206 | E4: 0.06461563 | F4: 0.0029714267 | G4: 0.018196632 | H4: -0.020076336 | I4: -0.028123444 | J4: 0.073433189 | K4: -0.013396289 | L4: -0.0082839521 | M4: -0.00038923017 | N4: 0.018151054
A5: 42826 | B5: 0.090493041 | C5: 0.043370857 | D5: 0.035416106 | E5: 0.043284961 | F5: 0.050212369 | G5: 0.034231351 | H5: 0.040430007 | I5: -0.070550576 | J5: -0.04252194 | K5: -0.028046745 | L5: 0.066276447 | M5: 0.0090912169 | N5: 0.02726998
A6: 42856 | B6: 0.067678363 | C6: 0.075276489 | D6: 0.063857459 | E6: 0.055805602 | F6: 0.014107267 | G6: 0.056396149 | H6: 0.058999701 | I6: -0.041328007 | J6: 0.38400767 | K6: 0.0087026222 | L6: 0.001715462 | M6: 0.01157621 | N6: 0.038973454
A7: 42887 | B7: -0.058160857 | C7: -0.02676399 | D7: 0.03202934 | E7: -0.026870139 | F7: 0.002255544 | G7: -0.01163737 | H7: -0.0092618778 | I7: -0.053887053 | J7: 0.0014409222 | K7: -0.010670905 | L7: 0.058454161 | M7: 0.004813832 | N7: -0.025833392
A8: 42917 | B8: 0.017016608 | C8: 0.020433884 | D8: -0.0073442312 | E8: 0.050260975 | F8: 0.021232131 | G8: 0.052284891 | H8: 0.042531935 | I8: 0.041919806 | J8: 0.12418373 | K8: 0.042111302 | L8: 0.034462302 | M8: 0.019348769 | N8: 0.040613194
A9: 42948 | B9: 0.010301428 | C9: -0.007268825 | D9: -0.045584726 | E9: 0.039225257 | F9: 0.015794825 | G9: 0.043035994 | H9: 0.030255322 | I9: -0.074198251 | J9: 0.042630698 | K9: 0.015965646 | L9: 0.036963662 | M9: 0.00054649233 | N9: 0.020735879
A10: 42979 | B10: 0.019345924 | C10: -0.019630838 | D10: 0.03275819 | E10: -0.047202237 | F10: 0.025095554 | G10: 0.059264816 | H10: -0.026310544 | I10: 0.098409699 | J10: 0.055075543 | K10: -0.013980709 | L10: -0.015334339 | M10: 0.019302895 | N10: -0.005129959
A11: 43009 | B11: 0.060921004 | C11: 0.14971654 | D11: 0.039467312 | E11: 0.038539099 | F11: 0.017073385 | G11: 0.053611898 | H11: 0.058137155 | I11: -0.082568807 | J11: 0.15684783 | K11: -0.05100022 | L11: 0.073372479 | M11: 0.022188175 | N11: 0.046063939
A12: 43040 | B12: 0.0030298924 | C12: 0.064662348 | D12: -0.070347077 | E12: 0.0021359223 | F12: 0.081853834 | G12: 0.011427035 | H12: 0.019152641 | I12: -0.01796875 | J12: -0.029495387 | K12: 0.042274728 | L12: 0.085386738 | M12: 0.028082601 | N12: 0.019717384
A13: 43070 | B13: 0.016628546 | C13: -0.0061865307 | D13: -0.051616136 | E13: -0.02426317 | F13: -0.016671221 | G13: 0.0059148003 | H13: -0.011705897 | I13: 0.072235481 | J13: -0.035932082 | K13: 0.021002334 | L13: -0.033790595 | M13: 0.0098316198 | N13: 0.003931679
A14: 2017 | B14: {=PRODUCT(1 + B2:B13) - 1} -> 0.32929522 | C14: {=PRODUCT(1 + C2:C13) - 1} -> 0.55956366 | D14: {=PRODUCT(1 + D2:D13) - 1} -> 0.0083921673 | E14: {=PRODUCT(1 + E2:E13) - 1} -> 0.26806749 | F14: {=PRODUCT(1 + F2:F13) - 1} -> 0.32377991 | G14: {=PRODUCT(1 + G2:G13) - 1} -> 0.46595642 | H14: {=PRODUCT(1 + H2:H13) - 1} -> 0.30746693 | I14: {=PRODUCT(1 + I2:I13) - 1} -> -0.19726027 | ... N14: {=PRODUCT(1 + N2:N13) - 1} -> 0.31465226
A15: SD | B15: =_xlfn.STDEV.S(B2:B13) -> 0.037867427 | C15: =_xlfn.STDEV.S(C2:C13) -> 0.052491036 | D15: =_xlfn.STDEV.S(D2:D13) -> 0.042996896 | E15: =_xlfn.STDEV.S(E2:E13) -> 0.042161764 | F15: =_xlfn.STDEV.S(F2:F13) -> 0.026336223 | G15: =_xlfn.STDEV.S(G2:G13) -> 0.022541381 | H15: =_xlfn.STDEV.S(H2:H13) -> 0.031995327 | I15: =_xlfn.STDEV.S(I2:I13) -> 0.058773354 | ... N15: =_xlfn.STDEV.S(N2:N13) -> 0.023219626
A16: 43101 | B16: 0.12228973 | C16: 0.24063892 | D16: 0.011360634 | E16: 0.0043466749 | F16: 0.041145159 | G16: 0.11654334 | H16: 0.014277483 | I16: 0.091853391 | J16: 0.27028424 | K16: -0.060296038 | L16: 0.074027034 | M16: 0.056178725 | N16: 0.087570621
A17: 43132 | B17: -0.066231328 | C17: 0.04242913 | D17: 0.043625914 | E17: -0.13860146 | F17: -0.053610361 | G17: 0.04 | H17: -0.039578336 | I17: -0.10790976 | J17: -0.015459723 | K17: -0.090572157 | L17: -0.044851761 | M17: -0.03894738 | N17: -0.012927981
A18: 43160 | B18: -0.060493514 | C18: -0.043049357 | D18: -0.0060075094 | E18: 0.06641163 | F18: -0.043677201 | G18: -0.003413746 | H18: 0.073480118 | I18: -0.013101767 | J18: -0.043008264 | K18: 0.0096790627 | L18: -0.053767244 | M18: -0.026884514 | N18: -0.042341965
A19: 43191 | B19: -0.017895366 | C19: 0.082074703 | D19: 0.009569378 | E19: 0.0063375903 | F19: 0.0011766372 | G19: 0.017755195 | H19: 0.0035510929 | I19: 0.058351343 | J19: -0.028895644 | K19: -0.087537841 | L19: 0.1046729 | M19: 0.002718801 | N19: 0.0050583901
A20: 43221 | B20: 0.079934811 | C20: 0.040539419 | D20: -0.078323772 | E20: -0.056892987 | F20: 0.022325502 | G20: 0.066472205 | H20: 0.011591727 | I20: 0.0016044341 | J20: 0.12135171 | K20: 0.011473597 | L20: 0.021615905 | M20: 0.021608353 | N20: 0.056729216
A21: 43252 | B21: 0.026536364 | C21: 0.043065254 | D21: -0.037889039 | E21: 0.083255638 | F21: -0.02609737 | G21: 0.03366295 | H21: 0.0073578192 | I21: -0.023882336 | J21: -0.060636341 | K21: 0.066830668 | L21: 0.015858557 | M21: 0.0048424002 | N21: 0.0092902922
A22: 43282 | B22: 0.086814442 | C22: 0.045675962 | D22: 0.096202532 | E22: 0.021842797 | F22: 0.10829611 | G22: 0.0075310401 | H22: 0.0030533437 | I22: 0.0073101596 | J22: 0.033600675 | K22: 0.036126057 | L22: 0.032118692 | M22: 0.036021586 | N22: 0.02796388
A23: 43313 | B23: 0.0037320122 | C23: 0.13236452 | D23: 0.074672825 | E23: -0.007170825 | F23: -0.0036956303 | G23: 0.088686869 | H23: 0.015279933 | I23: -0.06457346 | J23: 0.14628767 | K23: 0.025593472 | L23: 0.06018482 | M23: 0.030263219 | N23: 0.057806744
A24: 43344 | B24: -0.020068193 | C24: -0.0048243413 | D24: 0.050382044 | E24: -0.0074289776 | F24: 0.046145775 | G24: 0.032705511 | H24: -0.014697237 | I24: -0.035465484 | J24: 0.0012113439 | K24: 0.0033755274 | L24: -0.0090143783 | M24: 0.0042943009 | N24: -0.0046075542
A25: 43374 | B25: -0.096513901 | C25: -0.20219171 | D25: 0.018413276 | E25: -0.12508951 | F25: -0.091005524 | G25: -0.1120345 | H25: 0.029236277 | I25: -0.15774787 | J25: -0.24976158 | K25: 0.065481197 | L25: -0.017628928 | M25: -0.069403359 | N25: -0.085957264
A26: 43405 | B26: 0.017486108 | C26: 0.057671729 | D26: 0.096205357 | E26: 0.017267783 | F26: 0.013326889 | G26: 0.017200384 | H26: 0.053391304 | I26: -0.12102904 | J26: -0.22482356 | K26: 0.065741994 | L26: 0.076563995 | M26: 0.017859382 | N26: -0.0026498646
A27: 43435 | B27: -0.058297661 | C27: -0.11134975 | D27: -0.063734474 | E27: -0.084925249 | F27: -0.099693356 | G27: -0.061769533 | H27: -0.043420835 | I27: -0.2 | J27: -0.18314651 | K27: -0.027404507 | L27: -0.1145863 | M27: -0.091776956 | N27: -0.089212966
A28: 2018 | B28: {=PRODUCT(1 + B16:B27) - 1} -> -0.0080121511 | C28: {=PRODUCT(1 + C16:C27) - 1} -> 0.28431683 | D28: {=PRODUCT(1 + D16:D27) - 1} -> 0.21479524 | E28: {=PRODUCT(1 + E16:E27) - 1} -> -0.22209964 | F28: {=PRODUCT(1 + F16:F27) - 1} -> -0.10020717 | G28: {=PRODUCT(1 + G16:G27) - 1} -> 0.24636628 | H28: {=PRODUCT(1 + H16:H27) - 1} -> 0.11287534 | I28: {=PRODUCT(1 + I16:I27) - 1} -> -0.46460899 | ... N28: {=PRODUCT(1 + N16:N27) - 1} -> -0.0096302003
A29: SD | B29: =_xlfn.STDEV.S(B16:B27) -> 0.068332495 | C29: =_xlfn.STDEV.S(C16:C27) -> 0.11254681 | D29: =_xlfn.STDEV.S(D16:D27) -> 0.057936234 | E29: =_xlfn.STDEV.S(E16:E27) -> 0.069761107 | F29: =_xlfn.STDEV.S(F16:F27) -> 0.059785869 | G29: =_xlfn.STDEV.S(G16:G27) -> 0.061630325 | H29: =_xlfn.STDEV.S(H16:H27) -> 0.033502175 | I29: =_xlfn.STDEV.S(I16:I27) -> 0.086697436 | ... N29: =_xlfn.STDEV.S(N16:N27) -> 0.054317566
A30: 43466 | B30: 0.077447941 | C30: 0.14431713 | D30: 0.13701609 | E30: 0.11754028 | F30: 0.087117772 | G30: 0.11916247 | H30: 0.029685882 | I30: 0.22533259 | J30: 0.076794007 | K30: 0.049499565 | L30: 0.084617855 | M30: 0.078684405 | N30: 0.090107611
A31: 43497 | B31: 0.00058620292 | C31: -0.045905989 | D31: 0.047819434 | E31: 0.074873096 | F31: 0.072686765 | G31: 0.064604746 | H31: 0.048832272 | I31: -0.0033928975 | J31: 0.073098113 | K31: 0.021561107 | L31: -0.10355292 | M31: 0.02972893 | N31: 0.029911989
A32: 43525 | B32: 0.044685101 | C32: 0.085935737 | D32: 0.0562249 | E32: 0.070035419 | F32: 0.031479198 | G32: 0.047515238 | H32: 0.029831664 | I32: -0.011121198 | J32: 0.16400882 | K32: 0.055809234 | L32: 0.02080753 | M32: 0.017924288 | N32: 0.037357815
A33: 43556 | B33: 0.018752815 | C33: 0.081858767 | D33: 0.035948842 | E33: 0.0033983582 | F33: 0.092562295 | G33: 0.079804629 | H33: 0.005793503 | I33: -0.020426899 | J33: 0.0080196035 | K33: 0.023354157 | L33: -0.057388983 | M33: 0.039313435 | N33: 0.054992764
A34: 43586 | B34: -0.077116835 | C34: -0.078613251 | D34: 0.024190858 | E34: 0.068374753 | F34: -0.05367736 | G34: -0.010816551 | H34: 0.019389015 | I34: -0.18720712 | J34: -0.25160221 | K34: -0.033527423 | L34: 0.037456558 | M34: -0.065777726 | N34: -0.082251767
A35: 43617 | B35: -0.021418888 | C35: 0.066791732 | D35: 0.14008796 | E35: 0.038082299 | F35: 0.062564664 | G35: 0.051850968 | H35: 0.033550275 | I35: 0.14557509 | J35: 0.21237266 | K35: 0.065494121 | L35: 0.0091397849 | M35: 0.068930183 | N35: 0.073526876
A36: 43647 | B36: 0.12504618 | C36: -0.014179116 | D36: 0.021288756 | E36: -0.0043427393 | F36: -0.012200011 | G36: 0.029259441 | H36: 0.011275993 | I36: 0.0057876195 | J36: 0.027352218 | K36: 0.076516188 | L36: 0.020490963 | M36: 0.013128195 | N36: 0.02334797
A37: 43678 | B37: -0.02271384 | C37: -0.048473843 | D37: 0.12493005 | E37: 0.10790679 | F37: -0.045459817 | G37: 0.033422705 | H37: 0.057489019 | I37: -0.18864148 | J37: -0.0071597914 | K37: 0.018553033 | L37: -0.060278704 | M37: -0.018091653 | N37: -0.01899529
A38: 43709 | B38: 0.025711238 | C38: -0.022732774 | D38: -0.094515608 | E38: 0.036887898 | F38: 0.02782165 | G38: -0.034829584 | H38: 0.063492788 | I38: 0.053654024 | J38: 0.039161374 | K38: 0.034517175 | L38: -0.071282051 | M38: 0.017181168 | N38: 0.0071478103
A39: 43739 | B39: 0.030840035 | C39: 0.023474719 | D39: -0.039005631 | E39: -0.017371706 | F39: 0.020862884 | G39: 0.019295209 | H39: 0.022962359 | I39: -0.043312848 | J39: 0.1548095 | K39: 0.0010451841 | L39: 0.1628014 | M39: 0.020431747 | N39: 0.043800646
A40: 43770 | B40: 0.03597871 | C40: 0.013587293 | D40: -0.055881092 | E40: 0.00012350471 | F40: 0.033694205 | G40: 0.05570608 | H40: -0.018964504 | I40: 0.10737229 | J40: 0.078201174 | K40: -0.019677134 | L40: 0.1075188 | M40: 0.034047064 | N40: 0.040694134
...

Sheet Benchmark
C1: 2017 | D1: 2018 | E1: 2019 | F1: 2020 | G1: 2021 | H1: 2022
A2: GOOGL | B2: 0.1731 | C2: 0.32929522 | D2: -0.0080121511 | E2: 0.28176198 | F2: 0.30853598 | G2: 0.65295782 | H2: -0.39089553
A3: AMZN | B3: 0.1296 | C3: 0.55956366 | D3: 0.28431683 | E3: 0.23027757 | F3: 0.76256061 | G3: 0.023767781 | H3: -0.49615216
A4: BALL | B4: 0.05 | C4: 0.0083921673 | D4: 0.21479524 | E4: 0.40648108 | F4: 0.44085356 | G4: 0.033161623 | H4: -0.46878571
A5: EQIX | B5: 0.02 | C5: 0.26806749 | D5: -0.22209964 | E5: 0.65560472 | F5: 0.22353949 | G5: 0.18435128 | H5: -0.2255864
A6: HON | B6: 0.1 | C6: 0.32377991 | D6: -0.10020717 | E6: 0.33969119 | F6: 0.20169492 | G6: -0.019699107 | H6: 0.027768452
A7: MA | B7: 0.1 | C7: 0.46595642 | D7: 0.24636628 | E7: 0.58277233 | F7: 0.19541847 | G7: 0.0066677873 | H7: -0.032255371
A8: NEE | B8: 0.05 | C8: 0.30746693 | D8: 0.11287534 | E8: 0.39316534 | F8: 0.27436406 | G8: 0.21011017 | H8: -0.10454156
A9: SLB | B9: 0.02 | C9: -0.19726027 | D9: -0.46460899 | E9: 0.11419069 | F9: -0.45696517 | G9: 0.37196519 | H9: 0.78497496
A10: NVDA | B10: 0.2192 | C10: 0.81281619 | D10: -0.31007752 | E10: 0.76254682 | F10: 1.2192945 | G10: 1.2528533 | H10: -0.50311108 | J10: 0.31465226 | K10: -0.0096302003
A11: PG | B11: 0.0381 | C11: 0.092768792 | D11: 0.00043535046 | E11: 0.35879025 | F11: 0.11401121 | G11: 0.17565042 | H11: -0.073480866 | J11: 0.023219626
A12: UNH | B12: 0.1 | C12: 0.37753062 | D12: 0.13000091 | E12: 0.18007386 | F12: 0.19287026 | G12: 0.43190373 | H12: 0.055841001
C15: 2017 | D15: 2018 | E15: 2019 | F15: 2020 | G15: 2021 | H15: 2022
B16: Portfolio | C16: =SUMPRODUCT($B$2:$B$12,C2:C12) -> 0.44516005 | D16: =SUMPRODUCT($B$2:$B$12,D2:D12) -> -0.0022264899 | E16: =SUMPRODUCT($B$2:$B$12,E2:E12) -> 0.42506911 | F16: =SUMPRODUCT($B$2:$B$12,F2:F12) -> 0.51393935 | G16: =SUMPRODUCT($B$2:$B$12,G2:G12) -> 0.46260219 | H16: =SUMPRODUCT($B$2:$B$12,H2:H12) -> -0.25739009
B17: S&P 500 | C17: 0.19419965 | D17: -0.062372597 | E17: 0.28878074 | F17: 0.16258922 | G17: 0.26892736 | H17: -0.19442824
B18: NASDAQ | C18: 0.31465226 | D18: -0.0096302003 | E18: 0.37825749 | F18: 0.47565966 | G18: 0.26808823 | H18: -0.33070253
B20: CAGR | C20: 2017 | D20: 2018 | E20: 2019 | F20: 2020 | G20: 2021 | H20: 2022
B21: Portfolio | C21: =C16+1 -> 1.44516 | D21: =D16+1 -> 0.99777351 | E21: =E16+1 -> 1.4250691 | F21: =F16+1 -> 1.5139393 | G21: =G16+1 -> 1.4626022 | H21: =H16+1 -> 0.74260991
B22: S&P 500 | C22: =C17+1 -> 1.1941996 | D22: =D17+1 -> 0.9376274 | E22: =E17+1 -> 1.2887807 | F22: =F17+1 -> 1.1625892 | G22: =G17+1 -> 1.2689274 | H22: =H17+1 -> 0.80557176
B23: NASDAQ | C23: =C18+1 -> 1.3146523 | D23: =D18+1 -> 0.9903698 | E23: =E18+1 -> 1.3782575 | F23: =F18+1 -> 1.4756597 | G23: =G18+1 -> 1.2680882 | H23: =H18+1 -> 0.66929747
B25: CAGR | E25: CAGR
B26: Portfolio | C26: =PRODUCT(C21:H21) -> 3.3789307 | E26: Portfolio | F26: =C26^(1/6)-1 -> 0.22498249
B27: S&P 500 | C27: =PRODUCT(C22:H22) -> 1.7149583 | E27: NASDAQ | F27: =C28^(1/6)-1 -> 0.14449944
B28: NASDAQ | C28: =PRODUCT(C23:H23) -> 2.2474679 | E28: S&P 500 | F28: =C27^(1/6)-1 -> 0.094062819
D50: 2017 | G50: 2020 | J50: Wealth start
C51: Portfolio | D51: 0.44516005 | F51: Portfolio | G51: 0.51393935 | J51: Portifolio | L51: 2017 | M51: 2018 | N51: 2019 | O51: 2020 | P51: 2021 | Q51: 2022
C52: S&P 500 | D52: 0.19419965 | F52: S&P 500 | G52: 0.16258922 | J52: Portifolio | K52: 100 | L52: =K52*(1+C16) -> 144.516 | M52: =L52*(1+D16) -> 144.19424 | N52: =M52*(1+E16) -> 205.48676 | O52: =N52*(1+F16) -> 311.09449 | P52: =O52*(1+G16) -> 455.00748 | Q52: =P52*(1+H16) -> 337.89307
C53: NASDAQ | D53: 0.31465226 | F53: NASDAQ | G53: 0.47565966 | J53: S&P 500 | K53: 100 | L53: =K53*(1+C17) -> 119.41996 | M53: =L53*(1+D17) -> 111.97143 | N53: =M53*(1+E17) -> 144.30662 | O53: =N53*(1+F17) -> 167.76933 | P53: =O53*(1+G17) -> 212.88709 | Q53: =P53*(1+H17) -> 171.49583
J54: NASDAQ | K54: 100 | L54: =K54*(1+C18) -> 131.46523 | M54: =L54*(1+D18) -> 130.19919 | N54: =M54*(1+E18) -> 179.44801 | O54: =N54*(1+F18) -> 264.80419 | P54: =O54*(1+G18) -> 335.79507 | Q54: =P54*(1+H18) -> 224.74679
D55: 2018 | G55: 2021
C56: Portfolio | D56: -0.0022264899 | F56: Portfolio | G56: 0.46260219
C57: S&P 500 | D57: -0.062372597 | F57: S&P 500 | G57: 0.26892736
C58: NASDAQ | D58: -0.0096302003 | F58: NASDAQ | G58: 0.26808823
D60: 2019 | G60: 2022
C61: Portfolio | D61: 0.42506911 | F61: Portfolio | G61: -0.25739009
C62: S&P 500 | D62: 0.28878074 | F62: S&P 500 | G62: -0.19442824
C63: NASDAQ | D63: 0.37825749 | F63: NASDAQ | G63: -0.33070253

Sheet Metrics
B4: Expected | E4: Real | H4: SD active returns | K4: CAGR
B5: Expected Return | C5: 0.1708 | E5: CAGR | F5: =Benchmark!F26 -> 0.22498249 | H5: montlhy | I5: =_xlfn.STDEV.S(regression!Q3:Q74) -> 0.030014955 | K5: Portfolio | L5: 0.22498249
B6: Std Deviation | C6: 0.1367 | E6: Std Deviation | F6: =STD!R31 -> 0.063299042 | H6: annual | I6: =I5*SQRT(12) -> 0.10397486 | K6: S&P 500 | L6: 0.094062819
B7: Risk-Free Rate | C7: 0.0209 | E7: Risk-Free Rate | F7: 0.0209
E8: Beta | F8: 1.1470423
B10: Sharpe Ratio | C10: =(C5-C7)/C6 -> 1.0965618 | E10: Sharpe Ratio | F10: =(F5-F7)/F6 -> 3.2241007
E11: Treynor Ratio | F11: =(F5-F7)/F8 -> 0.17792063
E12: Information Ratio | F12: =(F5-L6)/I6 -> 1.2591474
B15: Sharpe Ratio | C15: 3.2241007 | E15: Treynor Ratio | F15: 0.17792063 | H15: Information Ratio | I15: 1.2591474
B17: CAGR | C17: 0.22498249 | E17: CAGR | F17: 0.22498249 | H17: Excess Return | I17: =L5-L6 -> 0.13091967
B18: Std Deviation | C18: 0.063299042 | E18: Risk-Free Rate | F18: 0.0209 | H18: Tracking Error | I18: =I5*SQRT(12) -> 0.10397486
B19: Risk-Free Rate | C19: 0.0209 | E19: Beta | F19: 1.1470423
E22: Metric | F22: Value | G22: Meaning
E23: Sharpe Ratio | F23: =C15 -> 3.2241007 | G23: Strong return per unit of total risk
E24: Trynor Ratio | F24: =F15 -> 0.17792063 | G24: Return per unit of market (beta) risk
E25: Information Ratio | F25: =I15 -> 1.2591474 | G25: Active return per unit of benchmark deviation
E26: Alpha (Annual) | F26: =(1 + regression!T23)^12 - 1 -> 0.10661348 | G26: Excess return not explained by the market (CAPM)
E27: Std Deviation | F27: =F6 -> 0.063299042 | G27: Portfolio return volatility

Sheet STD
A1: Ticker | B1: GOOGL | C1: AMZN | D1: BALL | E1: EQIX | F1: HON | G1: MA | H1: NEE | I1: SLB | J1: NVDA | K1: PG | L1: UNH | M1: S&P 500 | O1: Ticker | P1: GOOGL | Q1: AMZN | R1: BALL | S1: EQIX | T1: HON | U1: MA | V1: NEE | W1: SLB | X1: NVDA | Y1: PG | Z1: UNH | AA1: S&P 500
A2: 42736 | B2: 0.035005363 | C2: 0.098163682 | D2: 0.015851872 | E2: 0.077138301 | F2: 0.021319851 | G2: 0.029830508 | H2: 0.035660472 | I2: -0.0028588446 | J2: 0.022859284 | K2: 0.041864891 | L2: 0.012871782 | M2: 0.017884341 | O2: 2017 | P2: {=PRODUCT(1 + B2:B13) - 1} -> 0.32929522 | Q2: {=PRODUCT(1 + C2:C13) - 1} -> 0.55956366 | R2: {=PRODUCT(1 + D2:D13) - 1} -> 0.0083921673 | S2: {=PRODUCT(1 + E2:E13) - 1} -> 0.26806749 | T2: {=PRODUCT(1 + F2:F13) - 1} -> 0.32377991 | U2: {=PRODUCT(1 + G2:G13) - 1} -> 0.46595642 | V2: {=PRODUCT(1 + H2:H13) - 1} -> 0.30746693 | W2: {=PRODUCT(1 + I2:I13) - 1} -> -0.19726027 | ... AA2: {=PRODUCT(1 + M2:M13) - 1} -> 0.19419965
A3: 42767 | B3: 0.030163743 | C3: 0.026181571 | D3: -0.035798584 | E3: -0.023144059 | F3: 0.052232027 | G3: 0.038841343 | H3: 0.058842548 | I3: -0.040019114 | J3: -0.070525737 | K3: 0.039611872 | L3: 0.020234423 | M3: 0.037198261 | O3: SD | P3: =_xlfn.STDEV.S(B2:B13) -> 0.037867427 | Q3: =_xlfn.STDEV.S(C2:C13) -> 0.052491036 | R3: =_xlfn.STDEV.S(D2:D13) -> 0.042996896 | S3: =_xlfn.STDEV.S(E2:E13) -> 0.042161764 | T3: =_xlfn.STDEV.S(F2:F13) -> 0.026336223 | U3: =_xlfn.STDEV.S(G2:G13) -> 0.022541381 | V3: =_xlfn.STDEV.S(H2:H13) -> 0.031995327 | W3: =_xlfn.STDEV.S(I2:I13) -> 0.058773354 | ... AA3: =_xlfn.STDEV.S(M2:M13) -> 0.011217473
A4: 42795 | B4: 0.0033967311 | C4: 0.049110101 | D4: 0.0099279206 | E4: 0.06461563 | F4: 0.0029714267 | G4: 0.018196632 | H4: -0.020076336 | I4: -0.028123444 | J4: 0.073433189 | K4: -0.013396289 | L4: -0.0082839521 | M4: -0.00038923017 | O4: 2018 | P4: {=PRODUCT(1 + B14:B25) - 1} -> -0.0080121511 | Q4: {=PRODUCT(1 + C14:C25) - 1} -> 0.28431683 | R4: {=PRODUCT(1 + D14:D25) - 1} -> 0.21479524 | S4: {=PRODUCT(1 + E14:E25) - 1} -> -0.22209964 | T4: {=PRODUCT(1 + F14:F25) - 1} -> -0.10020717 | U4: {=PRODUCT(1 + G14:G25) - 1} -> 0.24636628 | V4: {=PRODUCT(1 + H14:H25) - 1} -> 0.11287534 | W4: {=PRODUCT(1 + I14:I25) - 1} -> -0.46460899 | ... AA4: {=PRODUCT(1 + M14:M25) - 1} -> -0.062372597
A5: 42826 | B5: 0.090493041 | C5: 0.043370857 | D5: 0.035416106 | E5: 0.043284961 | F5: 0.050212369 | G5: 0.034231351 | H5: 0.040430007 | I5: -0.070550576 | J5: -0.04252194 | K5: -0.028046745 | L5: 0.066276447 | M5: 0.0090912169 | O5: SD | P5: =_xlfn.STDEV.S(B14:B25) -> 0.068332495 | Q5: =_xlfn.STDEV.S(C14:C25) -> 0.11254681 | R5: =_xlfn.STDEV.S(D14:D25) -> 0.057936234 | S5: =_xlfn.STDEV.S(E14:E25) -> 0.069761107 | T5: =_xlfn.STDEV.S(F14:F25) -> 0.059785869 | U5: =_xlfn.STDEV.S(G14:G25) -> 0.061630325 | V5: =_xlfn.STDEV.S(H14:H25) -> 0.033502175 | W5: =_xlfn.STDEV.S(I14:I25) -> 0.086697436 | ... AA5: =_xlfn.STDEV.S(M14:M25) -> 0.044156806
A6: 42856 | B6: 0.067678363 | C6: 0.075276489 | D6: 0.063857459 | E6: 0.055805602 | F6: 0.014107267 | G6: 0.056396149 | H6: 0.058999701 | I6: -0.041328007 | J6: 0.38400767 | K6: 0.0087026222 | L6: 0.001715462 | M6: 0.01157621 | O6: 2019 | P6: {=PRODUCT(1 + B26:B37) - 1} -> 0.28176198 | Q6: {=PRODUCT(1 + C26:C37) - 1} -> 0.23027757 | R6: {=PRODUCT(1 + D26:D37) - 1} -> 0.40648108 | S6: {=PRODUCT(1 + E26:E37) - 1} -> 0.65560472 | T6: {=PRODUCT(1 + F26:F37) - 1} -> 0.33969119 | U6: {=PRODUCT(1 + G26:G37) - 1} -> 0.58277233 | V6: {=PRODUCT(1 + H26:H37) - 1} -> 0.39316534 | W6: {=PRODUCT(1 + I26:I37) - 1} -> 0.11419069 | ... AA6: {=PRODUCT(1 + M26:M37) - 1} -> 0.28878074
A7: 42887 | B7: -0.058160857 | C7: -0.02676399 | D7: 0.03202934 | E7: -0.026870139 | F7: 0.002255544 | G7: -0.01163737 | H7: -0.0092618778 | I7: -0.053887053 | J7: 0.0014409222 | K7: -0.010670905 | L7: 0.058454161 | M7: 0.004813832 | O7: SD | P7: =_xlfn.STDEV.S(B26:B37) -> 0.05107777 | Q7: =_xlfn.STDEV.S(C26:C37) -> 0.065819978 | R7: =_xlfn.STDEV.S(D26:D37) -> 0.076250939 | S7: =_xlfn.STDEV.S(E26:E37) -> 0.044398236 | T7: =_xlfn.STDEV.S(F26:F37) -> 0.048540156 | U7: =_xlfn.STDEV.S(G26:G37) -> 0.040452979 | V7: =_xlfn.STDEV.S(H26:H37) -> 0.022836157 | W7: =_xlfn.STDEV.S(I26:I37) -> 0.12378062 | ... AA7: =_xlfn.STDEV.S(M26:M37) -> 0.037412787
A8: 42917 | B8: 0.017016608 | C8: 0.020433884 | D8: -0.0073442312 | E8: 0.050260975 | F8: 0.021232131 | G8: 0.052284891 | H8: 0.042531935 | I8: 0.041919806 | J8: 0.12418373 | K8: 0.042111302 | L8: 0.034462302 | M8: 0.019348769 | O8: 2020 | P8: {=PRODUCT(1 + B38:B49) - 1} -> 0.30853598 | Q8: {=PRODUCT(1 + C38:C49) - 1} -> 0.76256061 | R8: {=PRODUCT(1 + D38:D49) - 1} -> 0.44085356 | S8: {=PRODUCT(1 + E38:E49) - 1} -> 0.22353949 | T8: {=PRODUCT(1 + F38:F49) - 1} -> 0.20169492 | U8: {=PRODUCT(1 + G38:G49) - 1} -> 0.19541847 | V8: {=PRODUCT(1 + H38:H49) - 1} -> 0.27436406 | W8: {=PRODUCT(1 + I38:I49) - 1} -> -0.45696517 | ... AA8: {=PRODUCT(1 + M38:M49) - 1} -> 0.16258922
A9: 42948 | B9: 0.010301428 | C9: -0.007268825 | D9: -0.045584726 | E9: 0.039225257 | F9: 0.015794825 | G9: 0.043035994 | H9: 0.030255322 | I9: -0.074198251 | J9: 0.042630698 | K9: 0.015965646 | L9: 0.036963662 | M9: 0.00054649233 | O9: SD | P9: =_xlfn.STDEV.S(B38:B49) -> 0.089118572 | Q9: =_xlfn.STDEV.S(C38:C49) -> 0.1000785 | R9: =_xlfn.STDEV.S(D38:D49) -> 0.061452749 | S9: =_xlfn.STDEV.S(E38:E49) -> 0.054251272 | T9: =_xlfn.STDEV.S(F38:F49) -> 0.097950281 | U9: =_xlfn.STDEV.S(G38:G49) -> 0.11468051 | V9: =_xlfn.STDEV.S(H38:H49) -> 0.074607168 | W9: =_xlfn.STDEV.S(I38:I49) -> 0.22843403 | ... AA9: =_xlfn.STDEV.S(M38:M49) -> 0.074848417
A10: 42979 | B10: 0.019345924 | C10: -0.019630838 | D10: 0.03275819 | E10: -0.047202237 | F10: 0.025095554 | G10: 0.059264816 | H10: -0.026310544 | I10: 0.098409699 | J10: 0.055075543 | K10: -0.013980709 | L10: -0.015334339 | M10: 0.019302895 | O10: 2021 | P10: {=PRODUCT(1 + B50:B61) - 1} -> 0.65295782 | Q10: {=PRODUCT(1 + C50:C61) - 1} -> 0.023767781 | R10: {=PRODUCT(1 + D50:D61) - 1} -> 0.033161623 | S10: {=PRODUCT(1 + E50:E61) - 1} -> 0.18435128 | T10: {=PRODUCT(1 + F50:F61) - 1} -> -0.019699107 | U10: {=PRODUCT(1 + G50:G61) - 1} -> 0.0066677873 | V10: {=PRODUCT(1 + H50:H61) - 1} -> 0.21011017 | W10: {=PRODUCT(1 + I50:I61) - 1} -> 0.37196519 | ... AA10: {=PRODUCT(1 + M50:M61) - 1} -> 0.26892736
A11: 43009 | B11: 0.060921004 | C11: 0.14971654 | D11: 0.039467312 | E11: 0.038539099 | F11: 0.017073385 | G11: 0.053611898 | H11: 0.058137155 | I11: -0.082568807 | J11: 0.15684783 | K11: -0.05100022 | L11: 0.073372479 | M11: 0.022188175 | O11: SD | P11: =_xlfn.STDEV.S(B50:B61) -> 0.065044196 | Q11: =_xlfn.STDEV.S(C50:C61) -> 0.057149453 | R11: =_xlfn.STDEV.S(D50:D61) -> 0.079898278 | S11: =_xlfn.STDEV.S(E50:E61) -> 0.059912921 | T11: =_xlfn.STDEV.S(F50:F61) -> 0.057796078 | U11: =_xlfn.STDEV.S(G50:G61) -> 0.082209886 | V11: =_xlfn.STDEV.S(H50:H61) -> 0.059811467 | W11: =_xlfn.STDEV.S(I50:I61) -> 0.10296062 | ... AA11: =_xlfn.STDEV.S(M50:M61) -> 0.031913769
A12: 43040 | B12: 0.0030298924 | C12: 0.064662348 | D12: -0.070347077 | E12: 0.0021359223 | F12: 0.081853834 | G12: 0.011427035 | H12: 0.019152641 | I12: -0.01796875 | J12: -0.029495387 | K12: 0.042274728 | L12: 0.085386738 | M12: 0.028082601 | O12: 2022 | P12: -0.39089553 | Q12: -0.49615216 | R12: -0.46878571 | S12: -0.2255864 | T12: 0.027768452 | U12: -0.032255371 | V12: -0.10454156 | W12: 0.78497496 | X12: -0.50311108 | Y12: -0.073480866 | Z12: 0.055841001 | AA12: -0.19442824
A13: 43070 | B13: 0.016628546 | C13: -0.0061865307 | D13: -0.051616136 | E13: -0.02426317 | F13: -0.016671221 | G13: 0.0059148003 | H13: -0.011705897 | I13: 0.072235481 | J13: -0.035932082 | K13: 0.021002334 | L13: -0.033790595 | M13: 0.0098316198 | O13: SD | P13: 0.077462741 | Q13: 0.12634635 | R13: 0.10150772 | S13: 0.096559965 | T13: 0.094196467 | U13: 0.092103934 | V13: 0.0891362 | W13: 0.17638329 | X13: 0.18135878 | Y13: 0.056819515 | Z13: 0.049266407 | AA13: 0.066310612
A14: 43101 | B14: 0.12228973 | C14: 0.24063892 | D14: 0.011360634 | E14: 0.0043466749 | F14: 0.041145159 | G14: 0.11654334 | H14: 0.014277483 | I14: 0.091853391 | J14: 0.27028424 | K14: -0.060296038 | L14: 0.074027034 | M14: 0.056178725
A15: 43132 | B15: -0.066231328 | C15: 0.04242913 | D15: 0.043625914 | E15: -0.13860146 | F15: -0.053610361 | G15: 0.04 | H15: -0.039578336 | I15: -0.10790976 | J15: -0.015459723 | K15: -0.090572157 | L15: -0.044851761 | M15: -0.03894738 | O15: Covarience Matrix
A16: 43160 | B16: -0.060493514 | C16: -0.043049357 | D16: -0.0060075094 | E16: 0.06641163 | F16: -0.043677201 | G16: -0.003413746 | H16: 0.073480118 | I16: -0.013101767 | J16: -0.043008264 | K16: 0.0096790627 | L16: -0.053767244 | M16: -0.026884514 | P16: GOOGL | Q16: AMZN | R16: BALL | S16: EQIX | T16: HON | U16: MA | V16: NEE | W16: SLB | X16: NVDA | Y16: PG | Z16: UNH | AA16: S&P 500
A17: 43191 | B17: -0.017895366 | C17: 0.082074703 | D17: 0.009569378 | E17: 0.0063375903 | F17: 0.0011766372 | G17: 0.017755195 | H17: 0.0035510929 | I17: 0.058351343 | J17: -0.028895644 | K17: -0.087537841 | L17: 0.1046729 | M17: 0.002718801 | O17: GOOGL | P17: =VARP(STD!$B$2:$B$73) -> 0.0047883961 | Q17: 0.0040144231 | R17: 0.0022227264 | S17: 0.00169515 | T17: 0.0024679958 | U17: 0.0024945176 | V17: 0.0017632782 | W17: 0.0035747737 | X17: 0.0054624514 | Y17: 0.0006775873 | Z17: 0.0018885157 | AA17: 0.0026153058
A18: 43221 | B18: 0.079934811 | C18: 0.040539419 | D18: -0.078323772 | E18: -0.056892987 | F18: 0.022325502 | G18: 0.066472205 | H18: 0.011591727 | I18: 0.0016044341 | J18: 0.12135171 | K18: 0.011473597 | L18: 0.021615905 | M18: 0.021608353 | O18: AMZN | P18: 0.0040144231 | Q18: =VARP(STD!$C$2:$C$73) -> 0.0085364592 | R18: 0.0025438653 | S18: 0.0025603998 | T18: 0.0020136203 | U18: 0.0029513333 | V18: 0.001740492 | W18: 0.0018209387 | X18: 0.0076578185 | Y18: 6.5474847e-05 | Z18: 0.0022527368 | AA18: 0.0029609148
A19: 43252 | B19: 0.026536364 | C19: 0.043065254 | D19: -0.037889039 | E19: 0.083255638 | F19: -0.02609737 | G19: 0.03366295 | H19: 0.0073578192 | I19: -0.023882336 | J19: -0.060636341 | K19: 0.066830668 | L19: 0.015858557 | M19: 0.0048424002 | O19: BALL | P19: 0.0022227264 | Q19: 0.0025438653 | R19: =VARP(STD!$D$2:$D$73) -> 0.0055176041 | S19: 0.0019082063 | T19: 0.0017927226 | U19: 0.0022205261 | V19: 0.0016704585 | W19: 0.00026770047 | X19: 0.0041166101 | Y19: 0.00094595692 | Z19: 0.00076722413 | AA19: 0.0016936528
A20: 43282 | B20: 0.086814442 | C20: 0.045675962 | D20: 0.096202532 | E20: 0.021842797 | F20: 0.10829611 | G20: 0.0075310401 | H20: 0.0030533437 | I20: 0.0073101596 | J20: 0.033600675 | K20: 0.036126057 | L20: 0.032118692 | M20: 0.036021586 | O20: EQIX | P20: 0.00169515 | Q20: 0.0025603998 | R20: 0.0019082063 | S20: =VARP(STD!$E$2:$E$73) -> 0.0042206089 | T20: 0.0010627446 | U20: 0.0011057728 | V20: 0.0020279434 | W20: -0.00073768169 | X20: 0.0038761821 | Y20: 0.0012839549 | Z20: 0.00099722643 | AA20: 0.0014034155
A21: 43313 | B21: 0.0037320122 | C21: 0.13236452 | D21: 0.074672825 | E21: -0.007170825 | F21: -0.0036956303 | G21: 0.088686869 | H21: 0.015279933 | I21: -0.06457346 | J21: 0.14628767 | K21: 0.025593472 | L21: 0.06018482 | M21: 0.030263219 | O21: HON | P21: 0.0024679958 | Q21: 0.0020136203 | R21: 0.0017927226 | S21: 0.0010627446 | T21: =VARP(STD!$F$2:$F$73) -> 0.0044995448 | U21: 0.0035990967 | V21: 0.0008147979 | W21: 0.0060990577 | X21: 0.0034216805 | Y21: 0.0013093381 | Z21: 0.0019934635 | AA21: 0.0026915255
A22: 43344 | B22: -0.020068193 | C22: -0.0048243413 | D22: 0.050382044 | E22: -0.0074289776 | F22: 0.046145775 | G22: 0.032705511 | H22: -0.014697237 | I22: -0.035465484 | J22: 0.0012113439 | K22: 0.0033755274 | L22: -0.0090143783 | M22: 0.0042943009 | O22: MA | P22: 0.0024945176 | Q22: 0.0029513333 | R22: 0.0022205261 | S22: 0.0011057728 | T22: 0.0035990967 | U22: =VARP(STD!$G$2:$G$73) -> 0.0054414121 | V22: 0.00038066637 | W22: 0.0058746805 | X22: 0.0038992805 | Y22: 0.0012057104 | Z22: 0.0017526487 | AA22: 0.0026416491
A23: 43374 | B23: -0.096513901 | C23: -0.20219171 | D23: 0.018413276 | E23: -0.12508951 | F23: -0.091005524 | G23: -0.1120345 | H23: 0.029236277 | I23: -0.15774787 | J23: -0.24976158 | K23: 0.065481197 | L23: -0.017628928 | M23: -0.069403359 | O23: NEE | P23: 0.0017632782 | Q23: 0.001740492 | R23: 0.0016704585 | S23: 0.0020279434 | T23: 0.0008147979 | U23: 0.00038066637 | V23: =VARP(STD!$H$2:$H$73) -> 0.0031428398 | W23: -0.00086514262 | X23: 0.0026720952 | Y23: 0.00067356809 | Z23: 0.00070753388 | AA23: 0.0011805952
A24: 43405 | B24: 0.017486108 | C24: 0.057671729 | D24: 0.096205357 | E24: 0.017267783 | F24: 0.013326889 | G24: 0.017200384 | H24: 0.053391304 | I24: -0.12102904 | J24: -0.22482356 | K24: 0.065741994 | L24: 0.076563995 | M24: 0.017859382 | O24: SLB | P24: 0.0035747737 | Q24: 0.0018209387 | R24: 0.00026770047 | S24: -0.00073768169 | T24: 0.0060990577 | U24: 0.0058746805 | V24: -0.00086514262 | W24: =VARP(STD!$I$2:$I$73) -> 0.019692492 | X24: 0.0049002793 | Y24: 0.00095638932 | Z24: 0.0028085784 | AA24: 0.0042962472
A25: 43435 | B25: -0.058297661 | C25: -0.11134975 | D25: -0.063734474 | E25: -0.084925249 | F25: -0.099693356 | G25: -0.061769533 | H25: -0.043420835 | I25: -0.2 | J25: -0.18314651 | K25: -0.027404507 | L25: -0.1145863 | M25: -0.091776956 | O25: NVDA | P25: 0.0054624514 | Q25: 0.0076578185 | R25: 0.0041166101 | S25: 0.0038761821 | T25: 0.0034216805 | U25: 0.0038992805 | V25: 0.0026720952 | W25: 0.0049002793 | X25: =VARP(STD!$J$2:$J$73) -> 0.019218649 | Y25: 0.00032981078 | Z25: 0.0020397519 | AA25: 0.0042043275
A26: 43466 | B26: 0.077447941 | C26: 0.14431713 | D26: 0.13701609 | E26: 0.11754028 | F26: 0.087117772 | G26: 0.11916247 | H26: 0.029685882 | I26: 0.22533259 | J26: 0.076794007 | K26: 0.049499565 | L26: 0.084617855 | M26: 0.078684405 | O26: PG | P26: 0.0006775873 | Q26: 6.5474847e-05 | R26: 0.00094595692 | S26: 0.0012839549 | T26: 0.0013093381 | U26: 0.0012057104 | V26: 0.00067356809 | W26: 0.00095638932 | X26: 0.00032981078 | Y26: =VARP(STD!$K$2:$K$73) -> 0.0022702169 | Z26: 0.00075537611 | AA26: 0.0009836735
A27: 43497 | B27: 0.00058620292 | C27: -0.045905989 | D27: 0.047819434 | E27: 0.074873096 | F27: 0.072686765 | G27: 0.064604746 | H27: 0.048832272 | I27: -0.0033928975 | J27: 0.073098113 | K27: 0.021561107 | L27: -0.10355292 | M27: 0.02972893 | O27: UNH | P27: 0.0018885157 | Q27: 0.0022527368 | R27: 0.00076722413 | S27: 0.00099722643 | T27: 0.0019934635 | U27: 0.0017526487 | V27: 0.00070753388 | W27: 0.0028085784 | X27: 0.0020397519 | Y27: 0.00075537611 | Z27: =VARP(STD!$L$2:$L$73) -> 0.0039128932 | AA27: 0.0017751894
A28: 43525 | B28: 0.044685101 | C28: 0.085935737 | D28: 0.0562249 | E28: 0.070035419 | F28: 0.031479198 | G28: 0.047515238 | H28: 0.029831664 | I28: -0.011121198 | J28: 0.16400882 | K28: 0.055809234 | L28: 0.02080753 | M28: 0.017924288 | O28: S&P 500 | P28: 0.0026153058 | Q28: 0.0029609148 | R28: 0.0016936528 | S28: 0.0014034155 | T28: 0.0026915255 | U28: 0.0026416491 | V28: 0.0011805952 | W28: 0.0042962472 | X28: 0.0042043275 | Y28: 0.0009836735 | Z28: 0.0017751894 | AA28: =VARP(STD!$M$2:$M$73) -> 0.0024097216
A29: 43556 | B29: 0.018752815 | C29: 0.081858767 | D29: 0.035948842 | E29: 0.0033983582 | F29: 0.092562295 | G29: 0.079804629 | H29: 0.005793503 | I29: -0.020426899 | J29: 0.0080196035 | K29: 0.023354157 | L29: -0.057388983 | M29: 0.039313435
A30: 43586 | B30: -0.077116835 | C30: -0.078613251 | D30: 0.024190858 | E30: 0.068374753 | F30: -0.05367736 | G30: -0.010816551 | H30: 0.019389015 | I30: -0.18720712 | J30: -0.25160221 | K30: -0.033527423 | L30: 0.037456558 | M30: -0.065777726 | O30: GOOGL | P30: 0.1731 | Q30: Variance | R30: {=MMULT(TRANSPOSE(P30:P40), MMULT(P17:Z27, P30:P40))} -> 0.0040067687
A31: 43617 | B31: -0.021418888 | C31: 0.066791732 | D31: 0.14008796 | E31: 0.038082299 | F31: 0.062564664 | G31: 0.051850968 | H31: 0.033550275 | I31: 0.14557509 | J31: 0.21237266 | K31: 0.065494121 | L31: 0.0091397849 | M31: 0.068930183 | O31: AMZN | P31: 0.1296 | Q31: ST | R31: {=SQRT(MMULT(TRANSPOSE(P30:P40), MMULT(P17:Z27, P30:P40)))} -> 0.063299042
A32: 43647 | B32: 0.12504618 | C32: -0.014179116 | D32: 0.021288756 | E32: -0.0043427393 | F32: -0.012200011 | G32: 0.029259441 | H32: 0.011275993 | I32: 0.0057876195 | J32: 0.027352218 | K32: 0.076516188 | L32: 0.020490963 | M32: 0.013128195 | O32: BALL | P32: 0.05
A33: 43678 | B33: -0.02271384 | C33: -0.048473843 | D33: 0.12493005 | E33: 0.10790679 | F33: -0.045459817 | G33: 0.033422705 | H33: 0.057489019 | I33: -0.18864148 | J33: -0.0071597914 | K33: 0.018553033 | L33: -0.060278704 | M33: -0.018091653 | O33: EQIX | P33: 0.02
A34: 43709 | B34: 0.025711238 | C34: -0.022732774 | D34: -0.094515608 | E34: 0.036887898 | F34: 0.02782165 | G34: -0.034829584 | H34: 0.063492788 | I34: 0.053654024 | J34: 0.039161374 | K34: 0.034517175 | L34: -0.071282051 | M34: 0.017181168 | O34: HON | P34: 0.1
A35: 43739 | B35: 0.030840035 | C35: 0.023474719 | D35: -0.039005631 | E35: -0.017371706 | F35: 0.020862884 | G35: 0.019295209 | H35: 0.022962359 | I35: -0.043312848 | J35: 0.1548095 | K35: 0.0010451841 | L35: 0.1628014 | M35: 0.020431747 | O35: MA | P35: 0.1
A36: 43770 | B36: 0.03597871 | C36: 0.013587293 | D36: -0.055881092 | E36: 0.00012350471 | F36: 0.033694205 | G36: 0.05570608 | H36: -0.018964504 | I36: 0.10737229 | J36: 0.078201174 | K36: -0.019677134 | L36: 0.1075188 | M36: 0.034047064 | O36: NEE | P36: 0.05
A37: 43800 | B37: 0.027068684 | C37: 0.026121724 | D37: -0.021041477 | E37: 0.029725677 | F37: -0.0086810417 | G37: 0.021763679 | H37: 0.035668463 | I37: 0.11049724 | J37: 0.085632555 | K37: 0.023267246 | L37: 0.050416265 | M37: 0.028589803 | O37: SLB | P37: 0.02
A38: 43831 | B38: 0.069725771 | C38: 0.087063815 | D38: 0.11612803 | E38: 0.010330649 | F38: -0.021355932 | G38: 0.058106434 | H38: 0.10753221 | I38: -0.16641791 | J38: 0.0048108797 | K38: -0.0022417934 | L38: -0.073236275 | M38: -0.0016280898 | O38: NVDA | P38: 0.2192
A39: 43862 | B39: -0.065278689 | C39: -0.062213748 | D39: -0.023829316 | E39: -0.028708053 | F39: -0.06379171 | G39: -0.081312908 | H39: -0.057568978 | I39: -0.1915846 | J39: 0.14228192 | K39: -0.091397849 | L39: -0.064195265 | M39: -0.084110469 | O39: PG | P39: 0.0381
A40: 43891 | B40: -0.13238753 | C40: 0.035020571 | D40: -0.082316208 | E40: 0.090380587 | F40: -0.17500154 | G40: -0.16775194 | H40: -0.048029752 | I40: -0.50203027 | J40: -0.02396398 | K40: -0.028526009 | L40: -0.021885786 | M40: -0.12511932 | O40: UNH | P40: 0.1
...

Sheet TopStock
C2: Ticker | D2: Start Price (Jan 2017) | E2: End Price (Dec 2022) | F2: Total Return (%) | G2: CAGR (%)
C3: SLB | D3: 65.67 | E3: 50.21 | F3: -23.55 | G3: -4.38
C4: BALL | D4: 34.86 | E4: 49.39 | F4: 41.68 | G4: 5.98
C5: EQIX | D5: 327.89 | E5: 622.83 | F5: 89.95 | G5: 11.29
C6: AMZN | D6: 41.17 | E6: 84 | F6: 104.01 | G6: 12.62
C7: PG | D7: 69.21 | E7: 141.49 | F7: 104.45 | G7: 12.66 | M7: TOP 5 | P7: Bottom 5
C8: HON | D8: 95.22 | E8: 203.16 | F8: 113.35 | G8: 13.46 | M8: Ticker | N8: CAGR (%) | P8: Ticker | Q8: CAGR (%)
C9: GOOGL | D9: 40.77 | E9: 87.7 | F9: 115.15 | G9: 13.62 | M9: NVDA | N9: 32.58 | P9: SLB | Q9: -4.38
C10: NEE | D10: 25.02 | E10: 77.73 | F10: 210.65 | G10: 20.79 | M10: UNH | N10: 23.58 | P10: BALL | Q10: 5.98
C11: MA | D11: 101.07 | E11: 342.12 | F11: 238.5 | G11: 22.54 | M11: MA | N11: 22.54 | P11: EQIX | Q11: 11.29
C12: UNH | D12: 142.34 | E12: 506.9 | F12: 256.12 | G12: 23.58 | M12: NEE | N12: 20.79 | P12: AMZN | Q12: 12.62
C13: NVDA | D13: 2.69 | E13: 14.6 | F13: 442.97 | G13: 32.58 | M13: GOOGL | N13: 13.62 | P13: PG | Q13: 12.66
C16: Ticker | D16: CAGR (%)
C17: NVDA | D17: 0.3258 | E17: Top
C18: UNH | D18: 0.2358 | E18: Top
C19: MA | D19: 0.2254 | E19: Top
C20: NEE | D20: 0.2079 | E20: Top
C21: GOOGL | D21: 0.1362 | E21: Top
C22: AMZN | D22: 0.1262 | E22: Bottom
C23: PG | D23: 0.1266 | E23: Bottom
C24: EQIX | D24: 0.1129 | E24: Bottom
C25: BALL | D25: 0.0598 | E25: Bottom
C26: SLB | D26: -0.0438 | E26: Bottom
D30: =D17/100 -> 0.003258
D31: =D18/100 -> 0.002358
D32: =D19/100 -> 0.002254
D33: =D20/100 -> 0.002079
D34: =D21/100 -> 0.001362
D35: =D22/100 -> 0.001262
D36: =D23/100 -> 0.001266
D37: =D24/100 -> 0.001129
D38: =D25/100 -> 0.000598 | S38: A
D39: =D26/100 -> -0.000438

Sheet regression
B2: Ticker | C2: GOOGL | D2: AMZN | E2: BALL | F2: EQIX | G2: HON | H2: MA | I2: NEE | J2: SLB | K2: NVDA | L2: PG | M2: UNH | N2: Portfolio | O2: S&P 500 | P2: S&P 500 | Q2: Active return | S2: 2017 | T2: {=PRODUCT(1 + C3:C14) - 1} -> 0.32929522 | U2: {=PRODUCT(1 + D3:D14) - 1} -> 0.55956366 | V2: {=PRODUCT(1 + E3:E14) - 1} -> 0.0083921673 | W2: {=PRODUCT(1 + F3:F14) - 1} -> 0.26806749 | X2: {=PRODUCT(1 + G3:G14) - 1} -> 0.32377991 | Y2: {=PRODUCT(1 + H3:H14) - 1} -> 0.46595642 | Z2: {=PRODUCT(1 + I3:I14) - 1} -> 0.30746693 | AA2: {=PRODUCT(1 + J3:J14) - 1} -> -0.19726027 | ... AD2: {=PRODUCT(1 + M3:M14) - 1} -> 0.37753062 | AE2: {=PRODUCT(1 + O3:O14) - 1} -> 0.19419965
B3: 42736 | C3: 0.035005363 | D3: 0.098163682 | E3: 0.015851872 | F3: 0.077138301 | G3: 0.021319851 | H3: 0.029830508 | I3: 0.035660472 | J3: -0.0028588446 | K3: 0.022859284 | L3: 0.041864891 | M3: 0.012871782 | N3: =SUMPRODUCT($S$17:$AC$17,C3:M3) -> 0.035850669 | O3: 0.017884341 | P3: 0.017884341 | Q3: =N3-P3 -> 0.017966328 | S3: SD | T3: =_xlfn.STDEV.S(C3:C14) -> 0.037867427 | U3: =_xlfn.STDEV.S(D3:D14) -> 0.052491036 | V3: =_xlfn.STDEV.S(E3:E14) -> 0.042996896 | W3: =_xlfn.STDEV.S(F3:F14) -> 0.042161764 | X3: =_xlfn.STDEV.S(G3:G14) -> 0.026336223 | Y3: =_xlfn.STDEV.S(H3:H14) -> 0.022541381 | Z3: =_xlfn.STDEV.S(I3:I14) -> 0.031995327 | AA3: =_xlfn.STDEV.S(J3:J14) -> 0.058773354 | ... AD3: =_xlfn.STDEV.S(M3:M14) -> 0.037968814 | AE3: =_xlfn.STDEV.S(O3:O14) -> 0.011217473
B4: 42767 | C4: 0.030163743 | D4: 0.026181571 | E4: -0.035798584 | F4: -0.023144059 | G4: 0.052232027 | H4: 0.038841343 | I4: 0.058842548 | J4: -0.040019114 | K4: -0.070525737 | L4: 0.039611872 | M4: 0.020234423 | N4: =SUMPRODUCT($S$17:$AC$17,C4:M4) -> 0.0056841602 | O4: 0.037198261 | P4: 0.037198261 | Q4: =N4-P4 -> -0.0315141 | S4: 2018 | T4: {=PRODUCT(1 + C15:C26) - 1} -> -0.0080121511 | U4: {=PRODUCT(1 + D15:D26) - 1} -> 0.28431683 | V4: {=PRODUCT(1 + E15:E26) - 1} -> 0.21479524 | W4: {=PRODUCT(1 + F15:F26) - 1} -> -0.22209964 | X4: {=PRODUCT(1 + G15:G26) - 1} -> -0.10020717 | Y4: {=PRODUCT(1 + H15:H26) - 1} -> 0.24636628 | Z4: {=PRODUCT(1 + I15:I26) - 1} -> 0.11287534 | AA4: {=PRODUCT(1 + J15:J26) - 1} -> -0.46460899 | ... AD4: {=PRODUCT(1 + M15:M26) - 1} -> 0.13000091 | AE4: {=PRODUCT(1 + O15:O26) - 1} -> -0.062372597
B5: 42795 | C5: 0.0033967311 | D5: 0.049110101 | E5: 0.0099279206 | F5: 0.06461563 | G5: 0.0029714267 | H5: 0.018196632 | I5: -0.020076336 | J5: -0.028123444 | K5: 0.073433189 | L5: -0.013396289 | M5: -0.0082839521 | N5: =SUMPRODUCT($S$17:$AC$17,C5:M5) -> 0.024049633 | O5: -0.00038923017 | P5: -0.00038923017 | Q5: =N5-P5 -> 0.024438863 | S5: SD | T5: =_xlfn.STDEV.S(C15:C26) -> 0.068332495 | U5: =_xlfn.STDEV.S(D15:D26) -> 0.11254681 | V5: =_xlfn.STDEV.S(E15:E26) -> 0.057936234 | W5: =_xlfn.STDEV.S(F15:F26) -> 0.069761107 | X5: =_xlfn.STDEV.S(G15:G26) -> 0.059785869 | Y5: =_xlfn.STDEV.S(H15:H26) -> 0.061630325 | Z5: =_xlfn.STDEV.S(I15:I26) -> 0.033502175 | AA5: =_xlfn.STDEV.S(J15:J26) -> 0.086697436 | ... AD5: =_xlfn.STDEV.S(M15:M26) -> 0.06348867 | AE5: =_xlfn.STDEV.S(O15:O26) -> 0.044156806
B6: 42826 | C6: 0.090493041 | D6: 0.043370857 | E6: 0.035416106 | F6: 0.043284961 | G6: 0.050212369 | H6: 0.034231351 | I6: 0.040430007 | J6: -0.070550576 | K6: -0.04252194 | L6: -0.028046745 | M6: 0.066276447 | N6: =SUMPRODUCT($S$17:$AC$17,C6:M6) -> 0.029214828 | O6: 0.0090912169 | P6: 0.0090912169 | Q6: =N6-P6 -> 0.020123611 | S6: 2019 | T6: {=PRODUCT(1 + C27:C38) - 1} -> 0.28176198 | U6: {=PRODUCT(1 + D27:D38) - 1} -> 0.23027757 | V6: {=PRODUCT(1 + E27:E38) - 1} -> 0.40648108 | W6: {=PRODUCT(1 + F27:F38) - 1} -> 0.65560472 | X6: {=PRODUCT(1 + G27:G38) - 1} -> 0.33969119 | Y6: {=PRODUCT(1 + H27:H38) - 1} -> 0.58277233 | Z6: {=PRODUCT(1 + I27:I38) - 1} -> 0.39316534 | AA6: {=PRODUCT(1 + J27:J38) - 1} -> 0.11419069 | ... AD6: {=PRODUCT(1 + M27:M38) - 1} -> 0.18007386 | AE6: {=PRODUCT(1 + O27:O38) - 1} -> 0.28878074
B7: 42856 | C7: 0.067678363 | D7: 0.075276489 | E7: 0.063857459 | F7: 0.055805602 | G7: 0.014107267 | H7: 0.056396149 | I7: 0.058999701 | J7: -0.041328007 | K7: 0.38400767 | L7: 0.0087026222 | M7: 0.001715462 | N7: =SUMPRODUCT($S$17:$AC$17,C7:M7) -> 0.11963131 | O7: 0.01157621 | P7: 0.01157621 | Q7: =N7-P7 -> 0.1080551 | S7: SD | T7: =_xlfn.STDEV.S(C27:C38) -> 0.05107777 | U7: =_xlfn.STDEV.S(D27:D38) -> 0.065819978 | V7: =_xlfn.STDEV.S(E27:E38) -> 0.076250939 | W7: =_xlfn.STDEV.S(F27:F38) -> 0.044398236 | X7: =_xlfn.STDEV.S(G27:G38) -> 0.048540156 | Y7: =_xlfn.STDEV.S(H27:H38) -> 0.040452979 | Z7: =_xlfn.STDEV.S(I27:I38) -> 0.022836157 | AA7: =_xlfn.STDEV.S(J27:J38) -> 0.12378062 | ... AD7: =_xlfn.STDEV.S(M27:M38) -> 0.079474996 | AE7: =_xlfn.STDEV.S(O27:O38) -> 0.037412787
